<mujoco model="hhfc">
  <compiler angle="radian" meshdir="../meshes/" eulerseq="zyx" />
  <statistic meansize="0.201559" extent="2.948112" center="0.00499457 0 0.337764" />

  <default>
      <joint limited="true" />
      <motor ctrllimited="true" />
      <geom condim="4" contype="1" conaffinity="15" solref="0.001 2" friction="0.9 0.2 0.2" />
      <equality solref="0.001 2" />
      <default class="visualgeom">
          <geom material="visualgeom" condim="1" contype="0" conaffinity="0" />
      </default>
      <default class="visualgeom2">
          <geom material="visualgeom2" condim="1" contype="0" conaffinity="0" />
      </default>
      <default class="obstacle">
          <geom material="obstacle" condim="3" contype="1" conaffinity="15" />
      </default>
      <default class="leg_joint_param">
          <joint damping="0.1" frictionloss="0.1" armature="0.1" />
          
      </default>
  </default>

  <asset>
    
    <texture name="grid" type="2d" builtin="checker" width="512" height="512" rgb1=".1 .2 .3" rgb2=".2 .3 .4" />
    <material name="grid" texture="grid" texrepeat="1 1" texuniform="true" reflectance=".2" />
  </asset>

  <option timestep="0.001" integrator="RK4">
    <flag frictionloss="enable" />
  </option>

  <visual>
    <map stiffness="300" force="0.1" zfar="30" />
    <rgba haze="0.15 0.25 0.35 1" />
    <global offwidth="2560" offheight="1440" elevation="-30" azimuth="120" />
  </visual>

  <asset>
    <mesh name="base_thorax" file="base_thorax.STL" />
    <mesh name="Lleg_hip_p" file="Lleg_hip_p.STL" />
    <mesh name="Lleg_hip_r" file="Lleg_hip_r.STL" />
    <mesh name="Lleg_hip_y" file="Lleg_hip_y.STL" />
    <mesh name="Lleg_knee" file="Lleg_knee.STL" />
    <mesh name="Lleg_ankle_p" file="Lleg_ankle_p.STL" />
    <mesh name="Lleg_ankle_r" file="Lleg_ankle_r.STL" />
    <mesh name="Rleg_hip_p" file="Rleg_hip_p.STL" />
    <mesh name="Rleg_hip_r" file="Rleg_hip_r.STL" />
    <mesh name="Rleg_hip_y" file="Rleg_hip_y.STL" />
    <mesh name="Rleg_knee" file="Rleg_knee.STL" />
    <mesh name="Rleg_ankle_p" file="Rleg_ankle_p.STL" />
    <mesh name="Rleg_ankle_r" file="Rleg_ankle_r.STL" />
    <mesh name="Larm_shoulder_p" file="Larm_shoulder_p.STL" />
    <mesh name="Rarm_shoulder_p" file="Rarm_shoulder_p.STL" />
  </asset>

  <worldbody>
    
    <light name="main_light" diffuse="2 2 2" specular="0.5 0.5 0.5" pos="0 0 40" dir="0 0 -1" castshadow="true" />
    
    <light name="aux_light1" diffuse=".8 .8 .8" pos=" 10 0 1" dir="-1 0 0" castshadow="false" />
    <light name="aux_light2" diffuse=".8 .8 .8" pos="-10 0 1" dir=" 1 0 0" castshadow="false" />
    <light name="aux_light3" diffuse=".8 .8 .8" pos="0  10 1" dir="0 -1 0" castshadow="false" />
    <light name="aux_light4" diffuse=".8 .8 .8" pos="0 -10 1" dir="0  1 0" castshadow="false" />
    
    <geom name="floor" type="plane" size="0 0 0.05" material="grid" />

    <body name="base_thorax" pos="0 0 0.92" euler="0 0 0">
      
      <inertial pos="0.0063842 0.00017156 0.099276" mass="21.7513" fullinertia="0.51774 0.41969 0.193013 3.96E-05 0.000772 0.000516" />
      <freejoint name="base_thorax" />
      <geom size="0.2 0.175 0.3" pos="0 0 0.2" type="box" rgba="0.89804 0.91765 0.92941 0" />
      <geom type="mesh" contype="0" conaffinity="0" group="1" density="0" rgba="0.89804 0.91765 0.92941 1" mesh="base_thorax" />
      <site name="imu_site" pos="0 0 0" size="0.02" rgba="1 0 0 1" type="sphere" />
      <site name="imu" size="0.01" pos="0.0 0 0.0" />

      <body name="Lleg_hip_p" pos="0.0074413 0.070763 -0.096701" quat="1 -1.49195e-05 9.221e-11 -6.1805e-06">
        
        <inertial pos="-0.0080076 0.037645 -0.018534" quat="0.414257 0.709337 0.188122 0.53837" mass="0.8" diaginertia="0.00249693 0.00187387 0.00185259" />
        <joint name="Lleg_hip_p_joint" pos="0 0 0" axis="0 -1 0" range="-1.5708 3.1416" class="leg_joint_param" />
        
        <geom type="mesh" contype="0" conaffinity="0" group="1" density="0" rgba="0.89804 0.91765 0.92941 1" mesh="Lleg_hip_p" />

        <body name="Lleg_hip_r" pos="-0.048264 0.063739 -0.039998" quat="1 -1.49194e-05 -1.55901e-05 6.18077e-06">
          
          <inertial pos="0.042398 0.0021906 -0.014152" quat="0.717776 -0.00466495 -0.115772 0.686566" mass="2.4" diaginertia="0.00470642 0.00421976 0.00322592" />
          <joint name="Lleg_hip_r_joint" pos="0 0 0" axis="1 0 0" range="-0.12217 0.52359" class="leg_joint_param" />
          <geom type="mesh" contype="0" conaffinity="0" group="1" density="0" rgba="0.89804 0.91765 0.92941 1" mesh="Lleg_hip_r" />
          <geom size="0.05 0.1" pos="0.05 0 -0.225" type="cylinder" rgba="0.89804 0.91765 0.92941 0" />

          <body name="Lleg_hip_y" pos="0.048263 0.0075949 -0.073228" quat="1 -0.0006421 0 0">
            
            <inertial pos="0.0012794 -0.012189 -0.11613" quat="0.996816 -0.0530944 -0.0162506 -0.0572273" mass="4.7" diaginertia="0.0299281 0.0291921 0.00657282" />
            <joint name="Lleg_hip_y_joint" pos="0 0 0" axis="0 0 1" range="-1.0472 1.2217" class="leg_joint_param" />
            <geom type="mesh" contype="0" conaffinity="0" group="1" density="0" rgba="0.75294 0.75294 0.75294 1" mesh="Lleg_hip_y" />

            <body name="Lleg_knee" pos="0 0 -0.27926">
              
              <inertial pos="-0.0093168 0.0004254 -0.1569" quat="0.997868 -0.0245164 0.0336298 0.0502756" mass="4.4" diaginertia="0.033405 0.0314582 0.0069106" />
              <joint name="Lleg_knee_joint" pos="0 0 0" axis="0 -1 0" range="-1.5708 0" class="leg_joint_param" />
              
              <geom type="mesh" contype="0" conaffinity="0" group="1" density="0" rgba="0.89804 0.91765 0.92941 1" mesh="Lleg_knee" />
              <geom size="0.05 0.125" pos="0 0 -0.175" type="cylinder" rgba="0.89804 0.91765 0.92941 0" />

              <body name="Lleg_ankle_p" pos="0 0 -0.35">
                
                <inertial pos="0.00066352 -5.5018e-08 8.196e-09" quat="0.499943 0.499943 -0.500057 0.500057" mass="0.24" diaginertia="0.000135 0.000113 5.24e-05" />
                <joint name="Lleg_ankle_p_joint" pos="0 0 0" axis="0 1 0" range="-1.6108 0.6108" class="leg_joint_param" />
                <geom type="mesh" contype="0" conaffinity="0" group="1" density="0" rgba="0.89804 0.91765 0.92941 1" mesh="Lleg_ankle_p" />

                <body name="Lleg_ankle_r">
                  
                  <inertial pos="0.021653 2.4998e-08 -0.044273" quat="1.13655e-06 0.717415 -1.10364e-06 0.696646" mass="0.88" diaginertia="0.00668964 0.005724 0.00130736" />
                  <joint name="Lleg_ankle_r_joint" pos="0 0 0" axis="1 0 0" range="-0.34453292519943295 0.34453292519943295" class="leg_joint_param" />
                  <geom type="mesh" contype="0" conaffinity="0" group="1" density="0" rgba="0.89804 0.91765 0.92941 1" mesh="Lleg_ankle_r" />
                  <geom name="Lleg_ankle_r" type="mesh" rgba="0.89804 0.91765 0.92941 0" mesh="Lleg_ankle_r" />
                </body>
              </body>
            </body>
          </body>
        </body>
      </body>

      <body name="Rleg_hip_p" pos="0.0074402 -0.070762 -0.096701" quat="1 1.49195e-05 -9.221e-11 -6.1805e-06">
        
        <inertial pos="-0.0080033 -0.037645 -0.018534" quat="0.709009 0.414898 0.538551 0.187424" mass="0.8" diaginertia="0.00249686 0.00187362 0.00185253" />
        <joint name="Rleg_hip_p_joint" pos="0 0 0" axis="0 -1 0" range="-1.5708 3.1416" class="leg_joint_param" />
        
        <geom type="mesh" contype="0" conaffinity="0" group="1" density="0" rgba="0.89804 0.91765 0.92941 1" mesh="Rleg_hip_p" />

        <body name="Rleg_hip_r" pos="-0.048261 -0.063738 -0.039998" quat="1 -1.49194e-05 -1.55901e-05 6.18077e-06">
          
          <inertial pos="0.042392 -0.0022474 -0.014239" quat="0.688789 -0.114585 -0.00306577 0.715843" mass="2.4" diaginertia="0.00471825 0.00423405 0.00323269" />
          <joint name="Rleg_hip_r_joint" pos="0 0 0" axis="1 0 0" range="-0.52359 0.12217" class="leg_joint_param" />
          <geom type="mesh" contype="0" conaffinity="0" group="1" density="0" rgba="0.75294 0.75294 0.75294 1" mesh="Rleg_hip_r" />
          <geom size="0.05 0.1" pos="0.05 0 -0.225" type="cylinder" rgba="0.75294 0.75294 0.75294 0" />

          <body name="Rleg_hip_y" pos="0.048263 -0.0075949 -0.073228" quat="1 -0.0006421 1.559e-05 1.00103e-08">
            
            <inertial pos="0.0012651 0.012199 -0.11598" quat="0.996226 0.0535852 -0.0154666 0.0665041" mass="4.7" diaginertia="0.0298237 0.0290669 0.00653037" />
            <joint name="Rleg_hip_y_joint" pos="0 0 0" axis="0 0 1" range="-1.2217 1.0472" class="leg_joint_param" />
            <geom type="mesh" contype="0" conaffinity="0" group="1" density="0" rgba="0.75294 0.75294 0.75294 1" mesh="Rleg_hip_y" />

            <body name="Rleg_knee" pos="0 0 -0.27926">
              
              <inertial pos="-0.0080323 -0.0016076 -0.15944" quat="0.503618 0.498429 -0.471667 0.524851" mass="4.4" diaginertia="0.0334195 0.0311732 0.00644732" />
              <joint name="Rleg_knee_joint" pos="0 0 0" axis="0 -1 0" range="-1.5708 0" class="leg_joint_param" />
              
              <geom type="mesh" contype="0" conaffinity="0" group="1" density="0" rgba="0.89804 0.91765 0.92941 1" mesh="Rleg_knee" />
              <geom size="0.05 0.125" pos="0 0 -0.175" type="cylinder" rgba="0.89804 0.91765 0.92941 0" />

              <body name="Rleg_ankle_p" pos="0 0 -0.35">
                
                <inertial pos="0.00099756 8.2521e-08 6.9572e-08" quat="0.5 0.5 -0.5 0.5" mass="0.24" diaginertia="0.000135 0.000113 5.3e-05" />
                <joint name="Rleg_ankle_p_joint" pos="0 0 0" axis="0 1 0" range="-1.6108 0.6108" class="leg_joint_param" />
                <geom type="mesh" contype="0" conaffinity="0" group="1" density="0" rgba="0.89804 0.91765 0.92941 1" mesh="Rleg_ankle_p" />

                <body name="Rleg_ankle_r">
                  
                  <inertial pos="0.021653 2.5592e-08 -0.044273" quat="0 0.717415 0 0.696646" mass="0.88" diaginertia="0.00668964 0.005725 0.00130736" />
                  <joint name="Rleg_ankle_r_joint" pos="0 0 0" axis="1 0 0" range="-0.34453292519943295 0.34453292519943295" class="leg_joint_param" />
                  <geom type="mesh" contype="0" conaffinity="0" group="1" density="0" rgba="0.89804 0.91765 0.92941 1" mesh="Rleg_ankle_r" />
                  <geom name="Rleg_ankle_r" type="mesh" rgba="0.89804 0.91765 0.92941 0" mesh="Rleg_ankle_r" />
                </body>
              </body>
            </body>
          </body>
        </body>
      </body>
      <body name="Larm_shoulder_p" pos="0.0074411 0.17676 0.2503" quat="1 -1.559e-05 0 0">
        
        <inertial pos="-4.0039e-06 0.029969 -0.17382" quat="0.706747 0.0225512 -0.0225512 0.706747" mass="0.9" diaginertia="0.0219046 0.021867 0.000591376" />
        <joint name="Larm_shoulder_p_joint" pos="0 0 0" axis="0 -1 0" range="-3.1416 3.1416" class="leg_joint_param" />
        <geom type="mesh" contype="0" conaffinity="0" group="1" density="0" rgba="0.89804 0.91765 0.92941 1" mesh="Larm_shoulder_p" />
      </body>

      <body name="Rarm_shoulder_p" pos="0.0074404 -0.17676 0.2503" quat="1 1.55905e-05 0.0008107 -1.26392e-08">
        
        <inertial pos="0.00016699 -0.03005 -0.17441" quat="0.706778 -0.0228932 0.0222331 0.706716" mass="0.9" diaginertia="0.0219559 0.021918 0.000591056" />
        <joint name="Rarm_shoulder_p_joint" pos="0 0 0" axis="0 -1 0" range="-3.1416 3.1416" class="leg_joint_param" />
        <geom type="mesh" contype="0" conaffinity="0" group="1" density="0" rgba="0.89804 0.91765 0.92941 1" mesh="Rarm_shoulder_p" />
      </body>
    </body>

  <geom pos="-2.746859022225715 -2.6626592713500146 -0.025" type="box" size="0.21438068472399224 0.17456294931491054 0.021094388660394987" quat="0.9931419082664951 0.00358903015080608 -0.012639269464260148 0.11617451430830701" rgba="0.6474682380758927 0.08616970601585204 0.26636205590825524 0.95" /><geom pos="-2.746859022225715 -2.3824431410976263 -0.025" type="box" size="0.3406596695759952 0.27824084657471493 0.022446563802419828" quat="0.9995211057068153 -0.0016220622648831704 -0.0015730875481068465 -0.030861846286318724" rgba="0.9565164126980599 0.03040688516111968 0.013076702140820448 0.95" /><geom pos="-2.746859022225715 -2.0986884201534455 -0.025" type="box" size="0.27111255429952374 0.15415703670905717 0.025383987700968266" quat="0.9991431844734695 -0.02485188430802185 -0.0015947010635096544 -0.03305658323349771" rgba="0.7660791621159154 0.22288109442096332 0.011039743463121254 0.95" /><geom pos="-2.746859022225715 -1.7620008825400424 -0.025" type="box" size="0.330527540745188 0.3382614817580731 0.02392501419294562" quat="0.9911505611839664 0.005616251664700872 -0.018629700721373786 -0.13130863274354465" rgba="0.7368623123122473 0.17063056580836614 0.09250712187938656 0.95" /><geom pos="-2.746859022225715 -1.4474718450775361 -0.025" type="box" size="0.1756084955310295 0.24463065652505772 0.02262456332042641" quat="0.9901007418455583 -0.02063440605470325 0.030965563065244943 -0.13533615994144702" rgba="0.8230911571288113 0.018230988093738288 0.1586778547774504 0.95" /><geom pos="-2.746859022225715 -1.136555037036747 -0.025" type="box" size="0.18484131171107848 0.21117351013483396 0.028803489139723568" quat="0.9983335587469571 0.030674014737103898 -0.029754446537895392 -0.03877993309389885" rgba="0.6729144353312907 0.06684355454420651 0.26024201012450277 0.95" /><geom pos="-2.746859022225715 -0.7998939856039269 -0.025" type="box" size="0.2115977666072346 0.20269661397934946 0.028852872250974767" quat="0.9935897543354874 0.0015863171417842426 -0.032548459326966074 -0.1082473162388451" rgba="0.3612984945461887 0.318655531914812 0.32004597353899933 0.95" /><geom pos="-2.746859022225715 -0.46651128661336605 -0.025" type="box" size="0.3305192354943255 0.31687704227140334 0.02889971900400983" quat="0.9944020005681883 0.02469455346672018 0.026573107698187538 -0.0992406682883818" rgba="0.0005731995907755083 0.2264093292346745 0.77301747117455 0.95" /><geom pos="-2.746859022225715 -0.15114901363421218 -0.025" type="box" size="0.28392114777520894 0.2088990113343982 0.022934392234865576" quat="0.9926538885254259 -0.024016043380286515 0.03019490808736676 -0.11467238020248377" rgba="0.36780378260298163 0.11328081151394007 0.5189154058830783 0.95" /><geom pos="-2.746859022225715 0.19770577721657734 -0.025" type="box" size="0.3100422069622168 0.3137134837467429 0.024897458830178774" quat="0.9980822801246403 0.018335449673101904 0.03412695690750389 0.04827964580149257" rgba="0.01639963939332123 0.887750512165751 0.09584984844092781 0.95" /><geom pos="-2.746859022225715 0.4931343194605149 -0.025" type="box" size="0.2968166268778294 0.2025935975714374 0.0275945506088394" quat="0.9973722275129453 -0.0033276303838943944 -0.021629274648398804 0.06906331254781971" rgba="0.2961008355550674 0.49260603983168544 0.21129312461324717 0.95" /><geom pos="-2.746859022225715 0.7612435410612202 -0.025" type="box" size="0.34417970482837157 0.32121243203538197 0.02159971162590194" quat="0.9989128705970244 0.0018944686592362657 -0.018998787875024212 0.04252686213902257" rgba="0.27882725112208306 0.4567362681673548 0.26443648071056214 0.95" /><geom pos="-2.746859022225715 1.0733445663048 -0.025" type="box" size="0.28414916405473123 0.3326544105006698 0.02753216278778036" quat="0.9930809852776298 -0.027285145186578184 0.01933995067729189 -0.11256839627515" rgba="0.1533198550418471 0.24183617831347906 0.6048439666446739 0.95" /><geom pos="-2.746859022225715 1.3530984254369338 -0.025" type="box" size="0.3184368947796923 0.20346858929715075 0.02141154492566274" quat="0.9982215341105589 0.0048062990975581595 0.02092777771650526 0.055612017107776336" rgba="0.21366165056168285 0.20601524633770665 0.5803231031006105 0.95" /><geom pos="-2.746859022225715 1.6385203273018396 -0.025" type="box" size="0.24239055726620728 0.2093263995435573 0.02795793333229358" quat="0.998016984996819 -0.01780396617218189 0.021747347049879028 0.05632201472506877" rgba="0.3874634458097229 0.42712751854905145 0.18540903564122563 0.95" /><geom pos="-2.746859022225715 1.9072746186900043 -0.025" type="box" size="0.2387876136801929 0.2637427571582574 0.027863976757534267" quat="0.995995763594756 0.0020799716851973866 -0.03069562039453694 -0.08393980883753635" rgba="0.5388582387888631 0.43480767429831524 0.026334086912821686 0.95" /><geom pos="-2.746859022225715 2.171841784497728 -0.025" type="box" size="0.22805450447690348 0.34559311407348453 0.021400464165676727" quat="0.9985809723325318 0.03392086814323728 -0.01160278820921417 -0.03938009275759575" rgba="0.06554180644568464 0.282884440893074 0.6515737526612413 0.95" /><geom pos="-2.746859022225715 2.4308077707804925 -0.025" type="box" size="0.2894583852121326 0.23775864418778306 0.027700374434813987" quat="0.9995877041649335 -0.018219141493699523 0.022191891317904847 -6.726993633524405e-05" rgba="0.5978738180675917 0.35061573193970136 0.051510449992706986 0.95" /><geom pos="-2.746859022225715 2.73265674757387 -0.025" type="box" size="0.2315793200979111 0.2507609483265572 0.029046704968874383" quat="0.999720409099084 0.015112689818235643 -0.015238624628853486 -0.009924442384283671" rgba="0.24856191511652115 0.4279347696867371 0.32350331519674175 0.95" /><geom pos="-2.746859022225715 3.0361301590917833 -0.025" type="box" size="0.20393078314691077 0.18205942059878688 0.02815322448828302" quat="0.9965901530142109 0.013607129610532506 -0.017566852128500586 -0.07946268712527581" rgba="0.9634886745390664 0.013045004298023286 0.023466321162910322 0.95" /><geom pos="-2.4146729139155454 -2.744015012232082 -0.025" type="box" size="0.20855273833213628 0.3235379001657119 0.029632086256777004" quat="0.9948056697326483 0.010360487617311315 0.029054672032961023 -0.09700600907761114" rgba="0.680677755889364 0.2502116407254 0.06911060338523606 0.95" /><geom pos="-2.4146729139155454 -2.4670723773179377 -0.025" type="box" size="0.19410716417589546 0.31200630377410427 0.024895710206792623" quat="0.9995394568588084 -0.01920580288723843 0.00966323164575326 0.021415724877184936" rgba="0.05604004587161526 0.040410040271006156 0.9035499138573786 0.95" /><geom pos="-2.4146729139155454 -2.204127640847571 -0.025" type="box" size="0.2646524497743194 0.17839631933771666 0.021253852628035055" quat="0.9999527359856167 0.006563108580335137 0.00712966222936381 -0.0007869670495242854" rgba="0.3070121940918721 0.45077961475227024 0.24220819115585768 0.95" /><geom pos="-2.4146729139155454 -1.8816691726584436 -0.025" type="box" size="0.2994932077754871 0.3061719078014398 0.026640759493913584" quat="0.9945139534850741 -0.02574436257660879 0.011380216357899691 -0.10074579293776842" rgba="0.897526610415709 0.03318716987557551 0.06928621970871546 0.95" /><geom pos="-2.4146729139155454 -1.601842778363249 -0.025" type="box" size="0.29692868644791365 0.1562410778586391 0.022649623877336145" quat="0.9923539455379349 0.0030260690177526636 -0.004182978465049726 -0.12331663461493848" rgba="0.9653110131828289 0.02745507901237634 0.0072339078047948015 0.95" /><geom pos="-2.4146729139155454 -1.3481221469669817 -0.025" type="box" size="0.21641045160667297 0.19030646723502112 0.029955558086903568" quat="0.9974311416487341 -0.013584565107618548 -0.026928514441358166 0.06497255089744443" rgba="0.25435625580290167 0.19840611301072436 0.547237631186374 0.95" /><geom pos="-2.4146729139155454 -1.0085246100354568 -0.025" type="box" size="0.23939951519321864 0.26581832184187626 0.02842621770628997" quat="0.9938297003330953 -0.03370955968433637 -0.012559488702111824 0.10492116833727871" rgba="0.1517747560413788 0.2361700788483378 0.6120551651102835 0.95" /><geom pos="-2.4146729139155454 -0.6918470991538199 -0.025" type="box" size="0.23870915545426646 0.21137593733181195 0.029051216133618767" quat="0.992125864826299 0.028749338617740237 -0.01749437563439854 -0.12063867826229342" rgba="0.09275383125435677 0.8391123634268751 0.06813380531876811 0.95" /><geom pos="-2.4146729139155454 -0.3560519671292339 -0.025" type="box" size="0.2826315857021241 0.2264671503425493 0.025904209635171586" quat="0.9899830148595803 -0.03504578771310886 0.02038056858337242 0.1352407315764096" rgba="0.6077818426678864 0.021267265717322573 0.37095089161479106 0.95" /><geom pos="-2.4146729139155454 -0.05596929711201959 -0.025" type="box" size="0.2504352060177603 0.2508339981639276 0.02456916379615489" quat="0.9907277115183178 -0.007377527872447299 -0.007797648180802954 -0.13543769931232696" rgba="0.28711148877719006 0.26315186141924196 0.449736649803568 0.95" /><geom pos="-2.4146729139155454 0.20393423462958538 -0.025" type="box" size="0.34697971554520746 0.31759441216601175 0.028312044296607313" quat="0.9891674203585065 -0.025501229353899462 -0.01287676694290533 0.14398503629139925" rgba="0.22875299688307071 0.008494997498961276 0.762752005617968 0.95" /><geom pos="-2.4146729139155454 0.5294238471842854 -0.025" type="box" size="0.17433126796795645 0.3477258467767002 0.029890251559478817" quat="0.9933308556380102 -0.011057194775725806 -0.023340950554599785 0.11236881110147169" rgba="0.23595378820130664 0.02531089993446059 0.7387353118642328 0.95" /><geom pos="-2.4146729139155454 0.8679479670723125 -0.025" type="box" size="0.16814437298592855 0.3168490977630391 0.020273304513767673" quat="0.9980444405860787 0.016202500404455155 -0.014053456325359362 -0.05871349045301402" rgba="0.13241422179114626 0.5629525515591476 0.30463322664970616 0.95" /><geom pos="-2.4146729139155454 1.1792250366374573 -0.025" type="box" size="0.3154022154702594 0.24411233820069903 0.02673506413083904" quat="0.9935672831078105 -0.027126403607478793 -0.0175214829912752 0.10854128154243772" rgba="0.231484889179288 0.2401462269874582 0.5283688838332539 0.95" /><geom pos="-2.4146729139155454 1.489503564150998 -0.025" type="box" size="0.3253560954615937 0.24281647493387348 0.023722468617041914" quat="0.9993342321253267 -0.03384855779531788 -0.013011273157338145 0.004009290272099338" rgba="0.5225192169954933 0.034915678798572936 0.44256510420593376 0.95" /><geom pos="-2.4146729139155454 1.7455711872869273 -0.025" type="box" size="0.3450747413914123 0.1914499256072491 0.024331077916035775" quat="0.9931619334854669 0.0034786710045555487 -0.03299759761922379 0.11193047518352928" rgba="0.08392051476061735 0.8770202082732859 0.03905927696609679 0.95" /><geom pos="-2.4146729139155454 2.031703873069935 -0.025" type="box" size="0.1613221338240276 0.2098581441659263 0.025229125571340848" quat="0.9998367236627728 0.003884199718632764 0.006360594337579737 -0.016461526281329273" rgba="0.024643675759519867 0.8925751500902516 0.08278117415022856 0.95" /><geom pos="-2.4146729139155454 2.288403402854482 -0.025" type="box" size="0.2664375817930531 0.27779014490392007 0.02212461742309788" quat="0.9980955883894727 -0.01118280083114511 0.003433826399468376 -0.06056690713006341" rgba="0.7545803317047637 0.10509616659871159 0.14032350169652474 0.95" /><geom pos="-2.4146729139155454 2.6067582091916446 -0.025" type="box" size="0.21349427077949093 0.312787085802846 0.023604880684636523" quat="0.9935709085589315 0.00028070933874496944 0.01531662883788623 0.11217028014892866" rgba="0.5922340398573899 0.16001522059446202 0.2477507395481481 0.95" /><geom pos="-2.4146729139155454 2.8993312600530174 -0.025" type="box" size="0.21245042447662618 0.2990231340208796 0.02178159289980157" quat="0.9995581944428935 -0.02700384208836235 -0.005017903952489052 0.011359096550919328" rgba="0.7331361035524095 0.2372716994915768 0.029592196956013644 0.95" /><geom pos="-2.075777638977739 -2.7349768515372546 -0.025" type="box" size="0.3084942211884638 0.23476762641085386 0.027082319008567807" quat="0.9979151322501008 0.007059093628485528 0.02323212458078948 0.05979821411104986" rgba="0.45413941295254345 0.5046805092730617 0.04118007777439481 0.95" /><geom pos="-2.075777638977739 -2.449076275473952 -0.025" type="box" size="0.2079037385483682 0.3350757754303966 0.0290269366678507" quat="0.9927538176408236 -0.010655855384200393 -0.024916946098393022 -0.11707030410283836" rgba="0.35613703256465723 0.3671478592043109 0.27671510823103185 0.95" /><geom pos="-2.075777638977739 -2.1640687027987155 -0.025" type="box" size="0.2971706847874947 0.16907495832994784 0.021264223281537147" quat="0.9909865372735389 0.004792864688736064 -0.0028527823410481297 0.13384533246845332" rgba="0.4640177150495006 0.3028884340228113 0.23309385092768808 0.95" /><geom pos="-2.075777638977739 -1.8647048141399185 -0.025" type="box" size="0.18265236091820936 0.31087666068358727 0.02439976115392808" quat="0.9917046393155983 -0.02009783054102593 -0.020264289290019086 -0.1253289437721139" rgba="0.5724128462766573 0.0645071067573528 0.36308004696598983 0.95" /><geom pos="-2.075777638977739 -1.5683797130893389 -0.025" type="box" size="0.2560230153979223 0.29530422872912876 0.020505297931043092" quat="0.9996075824646125 -0.006067633199246584 0.01756826539566554 0.020957599041865328" rgba="0.40759459424992295 0.13254375362758142 0.45986165212249563 0.95" /><geom pos="-2.075777638977739 -1.3055760368650693 -0.025" type="box" size="0.21783274029055127 0.23062087696955913 0.025575619658397677" quat="0.9970150113682682 0.027300082937019837 0.02772476399122284 -0.06668665563360268" rgba="0.020956010434947103 0.7808728065872255 0.19817118297782743 0.95" /><geom pos="-2.075777638977739 -1.013972542133345 -0.025" type="box" size="0.33122237411607536 0.25059817203437235 0.02178245493455394" quat="0.9965402065589862 -0.028251358597093715 0.00569838650768437 0.0779551527482344" rgba="0.9062123566273955 0.026981241594358905 0.06680640177824557 0.95" /><geom pos="-2.075777638977739 -0.7034637089583247 -0.025" type="box" size="0.2480916955351974 0.3117442671522279 0.020351083190837366" quat="0.9994651039490742 -0.026051515321958502 -0.014343836133467241 0.013604370712103728" rgba="0.4700654244954624 0.033041360527798457 0.49689321497673916 0.95" /><geom pos="-2.075777638977739 -0.3779779476062637 -0.025" type="box" size="0.29918252044357374 0.19253459816279045 0.029462090263548665" quat="0.9977963955225693 0.020702499370834966 0.010655691258725886 0.06213063532403274" rgba="0.92055495899188 0.061327109404792086 0.018117931603327912 0.95" /><geom pos="-2.075777638977739 -0.09429756654731092 -0.025" type="box" size="0.21275674821127782 0.2621390578451753 0.027422737741196555" quat="0.9995431017522411 -0.01354592301160374 0.026999575359030033 -0.0010576576498898742" rgba="0.10743325095795808 0.4748880402185012 0.41767870882354075 0.95" /><geom pos="-2.075777638977739 0.18121553001355828 -0.025" type="box" size="0.26835688355838594 0.2914289875039368 0.027205035786525215" quat="0.998992010154674 -0.002266790794186784 0.001184577333611729 0.044815422380691056" rgba="0.47975384995846104 0.06681267348777452 0.4534334765537644 0.95" /><geom pos="-2.075777638977739 0.4688331218517354 -0.025" type="box" size="0.23875786756978995 0.20754047208606358 0.022913106256553666" quat="0.9909902890706 0.009212472353524712 -0.01627882598283384 -0.13262117909868254" rgba="0.6625103876422883 0.14292388513344723 0.19456572722426446 0.95" /><geom pos="-2.075777638977739 0.8061763777032209 -0.025" type="box" size="0.2646506892774588 0.2814879881168401 0.02184250430015234" quat="0.9997052101165167 0.009918970629024719 0.008766787428311152 0.020353140439218254" rgba="0.9468036145881359 0.026864862237215705 0.026331523174648406 0.95" /><geom pos="-2.075777638977739 1.123604146007792 -0.025" type="box" size="0.2246653810039278 0.15465747250419834 0.020571780080654467" quat="0.9963513937650431 -0.022339005006067746 0.0306246090779182 0.07646569372352187" rgba="0.5287862567892653 0.19163181872907478 0.27958192448165997 0.95" /><geom pos="-2.075777638977739 1.443854132716245 -0.025" type="box" size="0.28828079302896037 0.32470715150214324 0.027794841888072745" quat="0.991852101263365 -0.007341371052842206 -0.002079977421685541 -0.12716598281158875" rgba="0.7897231974224626 0.15270138624598859 0.05757541633154886 0.95" /><geom pos="-2.075777638977739 1.7821329204123266 -0.025" type="box" size="0.224517966324267 0.3043197854021332 0.02707987535554518" quat="0.9959004876855353 0.034614271977836196 0.022346215474694037 -0.08052774340012381" rgba="0.12377740375340518 0.24054890886438027 0.6356736873822145 0.95" /><geom pos="-2.075777638977739 2.034393724085861 -0.025" type="box" size="0.34213375619054404 0.27178297158266596 0.026389925439120384" quat="0.9879815468370763 -0.03902768873650122 -0.02562585387843857 -0.1473520214802155" rgba="0.6635909614311597 0.02749430568373654 0.30891473288510374 0.95" /><geom pos="-2.075777638977739 2.32627897851261 -0.025" type="box" size="0.18337402241341427 0.18382475373008167 0.02538690432046884" quat="0.9951949308972803 -0.010432081120418924 -0.007574594432554531 -0.09706104635247388" rgba="0.2713555412457208 0.4650726039595819 0.2635718547946973 0.95" /><geom pos="-2.075777638977739 2.656731510117014 -0.025" type="box" size="0.16123362745044828 0.20564267293916366 0.02457372950806991" quat="0.9983843806140396 0.0006096389228920025 -0.0075338391440088505 -0.05631605591708811" rgba="0.167236425498965 0.5241060174346094 0.3086575570664256 0.95" /><geom pos="-2.075777638977739 2.948838326807838 -0.025" type="box" size="0.24920472572906954 0.2160386844855765 0.02855319217560009" quat="0.9939635919101324 -0.019328622860655096 -0.020278626433411558 0.10607336897351924" rgba="0.4743765021573554 0.22077219090055386 0.3048513069420907 0.95" /><geom pos="-1.7775192973497114 -2.6890811752939747 -0.025" type="box" size="0.17150320859965718 0.28727037449697695 0.02566094540502689" quat="0.9989933299630088 -0.003990339367170047 0.022254973810769327 0.03874429018366417" rgba="0.0947308536467576 0.3532752771651942 0.5519938691880482 0.95" /><geom pos="-1.7775192973497114 -2.3642741050676093 -0.025" type="box" size="0.2353273449505016 0.1550994788943158 0.021596098485106796" quat="0.9945126435394294 -0.013939810280330618 0.014322832124701028 0.10268953213201398" rgba="0.7246852576362481 0.04381170852646541 0.23150303383728646 0.95" /><geom pos="-1.7775192973497114 -2.1035008779686555 -0.025" type="box" size="0.23424123905157374 0.17505345969645586 0.02422595427053771" quat="0.9966574222513734 0.0051020464157720625 -0.02242177890771829 -0.07839142570608373" rgba="0.7391749454485464 0.1688754525967682 0.09194960195468535 0.95" /><geom pos="-1.7775192973497114 -1.7737598604015796 -0.025" type="box" size="0.29563870652899615 0.3320676037115373 0.029275798406543804" quat="0.9975632857573764 0.013659605772637863 0.02984557223509966 0.061564177059736123" rgba="0.3017378872016627 0.35251273602863725 0.3457493767697 0.95" /><geom pos="-1.7775192973497114 -1.452610985693206 -0.025" type="box" size="0.27880434622808425 0.23175711224292578 0.024011007582958488" quat="0.9977613163268056 0.022513894154554875 0.01829684868698902 -0.06025533619459042" rgba="0.9355439840086184 0.030687221653775545 0.03376879433760607 0.95" /><geom pos="-1.7775192973497114 -1.1401714761141961 -0.025" type="box" size="0.3335859565860443 0.22750768517909398 0.023732717673413305" quat="0.9946290376472645 0.02333125414722962 -0.023507987018790047 -0.09806173869108123" rgba="0.7659673485475537 0.06132754614153175 0.1727051053109146 0.95" /><geom pos="-1.7775192973497114 -0.8458739784806109 -0.025" type="box" size="0.22413028397525356 0.24530991258882587 0.02162357025579044" quat="0.9997517369306018 0.012743983652215607 -0.01827715391742243 3.208731274484449e-05" rgba="0.8660905650455318 0.09491679779762001 0.038992637156848156 0.95" /><geom pos="-1.7775192973497114 -0.5846339542232819 -0.025" type="box" size="0.3448144098869298 0.20784872369974738 0.02314595102968331" quat="0.9998518079557499 0.004297280587020382 -0.01216573099462444 0.011396951194996938" rgba="0.4117422613629562 0.43256323204528546 0.15569450659175832 0.95" /><geom pos="-1.7775192973497114 -0.2658500349190729 -0.025" type="box" size="0.28268660248032196 0.23668924219236043 0.02300504365506732" quat="0.9992898187606447 -0.025877720245139377 -0.02508166660108129 -0.011005076862259046" rgba="0.7281263174249959 0.2620055279512825 0.009868154623721592 0.95" /><geom pos="-1.7775192973497114 0.0667814942192062 -0.025" type="box" size="0.174995065189823 0.30492370062661656 0.029728638941226695" quat="0.9891297844756461 0.02527212396839643 -0.019807609969500078 0.1434965079734839" rgba="0.9424796550041776 0.0010081504270532675 0.0565121945687691 0.95" /><geom pos="-1.7775192973497114 0.3770861905466929 -0.025" type="box" size="0.33096258206383017 0.2593312935841778 0.020355437959337985" quat="0.9887011857755931 0.021341084061136446 0.007858439758898494 -0.1481646661710797" rgba="0.6941592730984967 0.1363459006481701 0.16949482625333323 0.95" /><geom pos="-1.7775192973497114 0.6594709473039302 -0.025" type="box" size="0.31910044424703765 0.33599839386483304 0.02515188819229955" quat="0.9885780227924047 0.02454320479235532 -0.01710912138564475 -0.14771053420725208" rgba="0.7158713149759169 0.027966044219507102 0.25616264080457596 0.95" /><geom pos="-1.7775192973497114 0.9920464351235525 -0.025" type="box" size="0.1718540976011626 0.3041646357491381 0.028901546835687426" quat="0.9986260222825505 0.018799444454537424 -0.02480490163635064 0.04215881121595536" rgba="0.6381530668374855 0.03465540820725095 0.32719152495526355 0.95" /><geom pos="-1.7775192973497114 1.285003344761705 -0.025" type="box" size="0.2235443235731351 0.30153747384280644 0.020002597959498186" quat="0.9982189347153779 -0.004298219465853111 -0.02855821128549404 -0.05220069207675619" rgba="0.45324132696277175 0.2667529760761488 0.28000569696107946 0.95" /><geom pos="-1.7775192973497114 1.6171141993553402 -0.025" type="box" size="0.15313405612043646 0.2734298849847915 0.026381217054844343" quat="0.9992397684101273 0.010675820025838322 -0.03424664825569841 -0.01526693085402181" rgba="0.4228612420957233 0.27377026403692734 0.3033684938673494 0.95" /><geom pos="-1.7775192973497114 1.876399893504069 -0.025" type="box" size="0.27458552351540505 0.3273185832410377 0.028889638528856836" quat="0.9996304270463041 0.015391522450374794 -0.009172769025555184 -0.02044433095719654" rgba="0.6975057742430056 0.140782944655676 0.16171128110131835 0.95" /><geom pos="-1.7775192973497114 2.168201290327149 -0.025" type="box" size="0.22442905450984119 0.17837199655047803 0.028680804723384513" quat="0.9988407635548138 -0.010716130014465218 0.010211649542360436 -0.045804102789745574" rgba="0.7952296333470833 0.04435368418340661 0.1604166824695101 0.95" /><geom pos="-1.7775192973497114 2.4931250125657547 -0.025" type="box" size="0.34924756824731235 0.2609433548254487 0.02883836724334259" quat="0.9998614997881072 0.009472383754399887 3.7332930875187047e-06 -0.013684121219454755" rgba="0.37453221014523297 0.1563331083018762 0.46913468155289084 0.95" /><geom pos="-1.7775192973497114 2.8112708304604013 -0.025" type="box" size="0.31419981682558107 0.3277686685758808 0.02175970328272177" quat="0.9973007868167493 -0.013423663731380053 0.029755194517620442 0.06576909810798909" rgba="0.05049605287071279 0.24463883999533964 0.7048651071339476 0.95" /><geom pos="-1.7775192973497114 3.124071712049104 -0.025" type="box" size="0.24279967365433727 0.2806247971462963 0.028584045108506095" quat="0.9959964678165706 0.033000680219576056 0.012030530137015922 -0.08220253978182483" rgba="0.430047915199675 0.36159320254038224 0.20835888225994276 0.95" /><geom pos="-1.4830028622273388 -2.726365138482711 -0.025" type="box" size="0.323203629588589 0.3281168431376238 0.02501097498113579" quat="0.9995420352820594 0.012095115696454902 0.016643300740158185 -0.0221907282656587" rgba="0.4701377658262057 0.27117636907345966 0.25868586510033464 0.95" /><geom pos="-1.4830028622273388 -2.377879057401258 -0.025" type="box" size="0.19692986163171236 0.17154948106098805 0.028127532486387" quat="0.990384311867742 -0.03375068691569359 0.02438503503020823 0.13192867772229552" rgba="0.7471560166423825 0.025546466373694312 0.22729751698392317 0.95" /><geom pos="-1.4830028622273388 -2.0731442082035576 -0.025" type="box" size="0.18987038435238796 0.2589549277362011 0.026075150807214554" quat="0.9994159257431814 -0.0018529530826139752 -0.03207383652222734 0.011646585187042252" rgba="0.8712966961139285 0.04477339125784384 0.0839299126282277 0.95" /><geom pos="-1.4830028622273388 -1.776680054611725 -0.025" type="box" size="0.24877532872091176 0.27209291625658427 0.020590396397700474" quat="0.9887985618153861 -0.013055006535807441 -0.005178118055780188 -0.14859393678604418" rgba="0.08695365694524837 0.03727761348228117 0.8757687295724704 0.95" /><geom pos="-1.4830028622273388 -1.508636875635212 -0.025" type="box" size="0.18949092686566588 0.27842717597926125 0.027327254635305692" quat="0.9949053708133355 0.024161229974618996 0.02546649664408196 -0.09450394511114388" rgba="0.5747629349634055 0.3984354491733431 0.026801615863251416 0.95" /><geom pos="-1.4830028622273388 -1.1609268503004357 -0.025" type="box" size="0.21230108571994716 0.1628144552462808 0.021485053870800283" quat="0.9949655809852446 0.022334795900097237 -0.0010846180712913048 -0.09769070145328618" rgba="0.9005327901244654 0.017298907061374633 0.08216830281415996 0.95" /><geom pos="-1.4830028622273388 -0.9074342313687 -0.025" type="box" size="0.324394061614025 0.30151928279292406 0.021551513540884706" quat="0.9997335979431021 -0.010553329661506848 -0.015275119147791812 0.013712443685059082" rgba="0.978070251204065 0.014968214692217055 0.006961534103717956 0.95" /><geom pos="-1.4830028622273388 -0.5726523951480784 -0.025" type="box" size="0.31310128409123916 0.17569092724173213 0.0223943217050864" quat="0.9986329055547748 0.007609586633195534 0.011987044661916883 -0.05030631068537481" rgba="0.3105028546331827 0.0952550304433043 0.594242114923513 0.95" /><geom pos="-1.4830028622273388 -0.26679182468852813 -0.025" type="box" size="0.28884347726471105 0.3438791069112025 0.027615473298863314" quat="0.9910476741989578 -0.022507650902956564 0.012499931799539494 -0.1310025374589138" rgba="0.9691530357946273 0.0024444717073725535 0.028402492498000143 0.95" /><geom pos="-1.4830028622273388 0.019125084732797504 -0.025" type="box" size="0.15580683038459187 0.22389833829994343 0.022909176762640385" quat="0.9989287494359801 0.016405773337134926 0.031111693129464775 -0.030071027619578895" rgba="0.18473717144791268 0.4823510865493919 0.3329117420026954 0.95" /><geom pos="-1.4830028622273388 0.2885120017701581 -0.025" type="box" size="0.23430647384535075 0.30623727891070385 0.028557708542150756" quat="0.9987724038911907 0.019706174471645334 0.0249869261127404 0.03796057740000485" rgba="0.6608252285980838 0.336344563113041 0.0028302082888752023 0.95" /><geom pos="-1.4830028622273388 0.598048913173415 -0.025" type="box" size="0.18320203620067443 0.2748906358584519 0.025700079454579368" quat="0.9891606303914244 0.017527607352672038 -0.021438492461674404 -0.14420270907684407" rgba="0.12475737253049235 0.11586589118427094 0.7593767362852367 0.95" /><geom pos="-1.4830028622273388 0.9412885316801267 -0.025" type="box" size="0.18649395849030026 0.34406278255253825 0.025531874578231056" quat="0.997211420710956 0.01648968959856594 -0.004531164126955308 0.07264255703259884" rgba="0.8759457610401 0.1115406846836853 0.012513554276214672 0.95" /><geom pos="-1.4830028622273388 1.233397902607769 -0.025" type="box" size="0.189290998137036 0.2012018712200463 0.02460075353389328" quat="0.9990177693906124 0.001171029429876351 0.025264979802560168 0.03638414390165042" rgba="0.5407570209377671 0.27254879347702443 0.18669418558520845 0.95" /><geom pos="-1.4830028622273388 1.4929083458799486 -0.025" type="box" size="0.15150777192163928 0.22378879349351055 0.021625843831378968" quat="0.999103079308334 -0.02437862727951823 0.004477196835586951 0.03433182426068678" rgba="0.6119699417244852 0.14763331055018608 0.24039674772532876 0.95" /><geom pos="-1.4830028622273388 1.8090745744093253 -0.025" type="box" size="0.3360385882660623 0.28009994186552145 0.029993061927826567" quat="0.9993879170056285 -0.005721245516621068 0.03323893962853156 -0.009286096341316559" rgba="0.7688360775818927 0.17119109034618776 0.059972832071919585 0.95" /><geom pos="-1.4830028622273388 2.084224098534343 -0.025" type="box" size="0.18509176724011833 0.20893820942658148 0.023425622039200997" quat="0.9938294780451012 -0.012467010139926545 -0.02020150036743444 -0.10834870377478889" rgba="0.3786487506242585 0.3299202743040544 0.2914309750716871 0.95" /><geom pos="-1.4830028622273388 2.4029025710250025 -0.025" type="box" size="0.3215842938766217 0.24417236080424282 0.026623751099852183" quat="0.9990086648287391 0.03190725803286657 -0.004526700371938867 -0.030710315297416038" rgba="0.9698695196603702 0.01463561887233035 0.01549486146729949 0.95" /><geom pos="-1.4830028622273388 2.7052357701351815 -0.025" type="box" size="0.23211450401219283 0.2984371053150648 0.027264922551280383" quat="0.9993346827959187 0.018547814623524592 0.002824327302979618 0.0312760852594651" rgba="0.47555617521590643 0.3506728995454043 0.17377092523868926 0.95" /><geom pos="-1.4830028622273388 3.0221884652941924 -0.025" type="box" size="0.2052035785328759 0.3320289568569566 0.02180099595663974" quat="0.9949535226199627 -0.003154284304274752 0.015937196906976578 -0.09901284801177869" rgba="0.1488693503356835 0.1959731014771964 0.6551575481871201 0.95" /><geom pos="-1.1734202950233845 -2.7330481811463763 -0.025" type="box" size="0.22431049591830074 0.27442263922745863 0.022700664585117786" quat="0.996696348199325 0.03159506675008832 0.011818139060210658 -0.07388147827663473" rgba="0.7712386792492291 0.03435185710939281 0.19440946364137812 0.95" /><geom pos="-1.1734202950233845 -2.432671368056297 -0.025" type="box" size="0.3189356847278565 0.2621595525121854 0.02173462245144702" quat="0.9968192964295558 -0.0032982306006687657 -0.015099103809795292 -0.07818202481856856" rgba="0.7897405227436347 0.16377157063700792 0.046487906619357366 0.95" /><geom pos="-1.1734202950233845 -2.1384293016137748 -0.025" type="box" size="0.3311911404707287 0.3006081515981316 0.02430600325339635" quat="0.9993579454873667 0.006071549670315981 0.031804722657896 0.015339253323569417" rgba="0.3393904544273544 0.014705947327732217 0.6459035982449134 0.95" /><geom pos="-1.1734202950233845 -1.804351319441831 -0.025" type="box" size="0.2709708427350713 0.2853699501464332 0.028736015046387998" quat="0.9940385926519368 -0.014348162809656303 0.003982017177468253 0.10800717606595822" rgba="0.7376952609971733 0.25946285241831324 0.0028418865845134533 0.95" /><geom pos="-1.1734202950233845 -1.5261258069832195 -0.025" type="box" size="0.16466483575885038 0.17054021748220816 0.02507877861427721" quat="0.9952596001055419 -0.002720910285528418 0.024928267713807885 -0.09396545383152004" rgba="0.9733315302387202 0.011380215383063646 0.015288254378216144 0.95" /><geom pos="-1.1734202950233845 -1.2141244074716009 -0.025" type="box" size="0.24788318616779675 0.1641977652688314 0.027929997309299587" quat="0.99738485310878 0.027831438085078285 -0.033374451586418524 -0.05774956125028025" rgba="0.7630100718264242 0.026197947535314743 0.21079198063826105 0.95" /><geom pos="-1.1734202950233845 -0.9403072416484113 -0.025" type="box" size="0.19615352879646733 0.23218405448269855 0.027887952556174718" quat="0.9927212017058291 0.022989400677341128 -0.015750203856325404 0.11716669415288296" rgba="0.6601372310931998 0.029505956765187982 0.31035681214161226 0.95" /><geom pos="-1.1734202950233845 -0.6875363657783211 -0.025" type="box" size="0.16458756349606413 0.2019455743344433 0.02160860542475662" quat="0.9943408751439139 0.016015447157877134 -0.005132112107802608 -0.10489704903228611" rgba="0.35680109246105807 0.309065979240679 0.3341329282982629 0.95" /><geom pos="-1.1734202950233845 -0.4248801096588517 -0.025" type="box" size="0.22081183948496913 0.15618092439143444 0.02619771577363842" quat="0.9889099752957672 0.020858509340369424 -0.006704518528704685 0.1468912277160251" rgba="0.6355223716105388 0.28101386575796267 0.08346376263149852 0.95" /><geom pos="-1.1734202950233845 -0.1341654827453378 -0.025" type="box" size="0.30091296278311686 0.24803406700363878 0.02213004503097176" quat="0.9908789917186646 0.029367871936694764 0.02603473453108661 0.12891293366612963" rgba="0.6431866568146809 0.15511302632421672 0.20170031686110237 0.95" /><geom pos="-1.1734202950233845 0.18122223040827645 -0.025" type="box" size="0.1851142894926689 0.26807348056277536 0.025896511749105858" quat="0.9932630929896545 0.0023790198929257234 -0.009987629618637707 0.11542536819770137" rgba="0.9934109587653918 0.005745424596162896 0.0008436166384453436 0.95" /><geom pos="-1.1734202950233845 0.5103935907309562 -0.025" type="box" size="0.23331214041703657 0.3413727254149036 0.022203953536547305" quat="0.9903139480830642 -0.015063530390862865 0.02582830306318846 -0.13558861694542726" rgba="0.5043643334019772 0.012141661904353925 0.4834940046936689 0.95" /><geom pos="-1.1734202950233845 0.771579998806061 -0.025" type="box" size="0.23006795584060066 0.33603330611575716 0.027645194907607716" quat="0.9884500017243023 0.004667032491033895 -0.028477575875903785 0.14877446209342043" rgba="0.9949818073800029 0.0021678685812500983 0.0028503240387470433 0.95" /><geom pos="-1.1734202950233845 1.1175968468287536 -0.025" type="box" size="0.22654250219800098 0.2149258594213018 0.02716536736799945" quat="0.9997626425408179 0.00404268719931776 0.01179278295217901 0.017867443304846426" rgba="0.06983902775109019 0.2927917112965447 0.6373692609523651 0.95" /><geom pos="-1.1734202950233845 1.373156998666178 -0.025" type="box" size="0.16537996048945475 0.17460577654749043 0.021706185000151795" quat="0.9993957939877629 0.031523855504718284 -0.014114162099150028 -0.0038838025085855482" rgba="0.7523007027461995 0.044331563564197804 0.20336773368960265 0.95" /><geom pos="-1.1734202950233845 1.7074665977517558 -0.025" type="box" size="0.3115161334478236 0.23814739352960762 0.02966976604454062" quat="0.9918730428224575 0.027803023255866012 -0.020067517126036227 0.12252409386055234" rgba="0.3395836166899555 0.07012064600492388 0.5902957373051206 0.95" /><geom pos="-1.1734202950233845 1.974806085875482 -0.025" type="box" size="0.23742240207577228 0.2874904346495698 0.028969405144024" quat="0.9967254606437725 3.76180665833442e-05 -0.0135093373594664 -0.079723600605145" rgba="0.6343278522889089 0.3609723899608821 0.004699757750209033 0.95" /><geom pos="-1.1734202950233845 2.2528690297989806 -0.025" type="box" size="0.15590756647267645 0.2468458421976791 0.027709718639589903" quat="0.9982588465482835 -0.010622232985434112 0.01775571982322147 -0.05523746797286215" rgba="0.8736544693510088 0.03265902332518127 0.09368650732380995 0.95" /><geom pos="-1.1734202950233845 2.539849367076501 -0.025" type="box" size="0.15187616198660733 0.1944465835114876 0.022425360815342542" quat="0.9905266896757328 -0.02474229599636665 0.03304558264912311 -0.13096826064449024" rgba="0.4139329581918383 0.43029419193664825 0.15577284987151346 0.95" /><geom pos="-1.1734202950233845 2.798016406355231 -0.025" type="box" size="0.19883873117070988 0.25907692438499524 0.02301253563398399" quat="0.9956101452430932 0.022039230383278378 0.01470816199566921 -0.08976848547150894" rgba="0.02900452882094895 0.26802367016530426 0.7029718010137468 0.95" /><geom pos="-0.8675175148248964 -2.7106587050325515 -0.025" type="box" size="0.19322981360857389 0.2013759856917569 0.023812427158958552" quat="0.9990455561946505 0.019430516205250006 -0.015647126576506815 -0.03585525230168473" rgba="0.5554436545900862 0.09832543098663424 0.3462309144232796 0.95" /><geom pos="-0.8675175148248964 -2.432547901455205 -0.025" type="box" size="0.28501360529143055 0.3105844823099855 0.0218663425299351" quat="0.997385289949981 -0.026527855938911847 -0.015465341048529844 -0.06541925922027478" rgba="0.2763934845735728 0.7028552428547753 0.02075127257165188 0.95" /><geom pos="-0.8675175148248964 -2.1626561748007727 -0.025" type="box" size="0.227522221714104 0.24224955967088393 0.027820403838942593" quat="0.9994765690289632 0.024635363427592163 -0.008269198670686009 -0.019269332739543194" rgba="0.9081724686027906 0.043375630741101893 0.048451900656107556 0.95" /><geom pos="-0.8675175148248964 -1.860811381795739 -0.025" type="box" size="0.19757149416651426 0.3000680213075433 0.020905233884537473" quat="0.9991095893090101 0.00851357949660829 -0.02437189774324791 -0.03337001820989756" rgba="0.4885287039349018 0.48023912224139087 0.031232173823707354 0.95" /><geom pos="-0.8675175148248964 -1.5425458939924674 -0.025" type="box" size="0.2822859984981504 0.3181832279427197 0.021962054214283835" quat="0.9902663227018628 0.005737508124936133 -0.010677507220741574 0.13865670543683678" rgba="0.17307617069786385 0.6081420148276466 0.21878181447448952 0.95" /><geom pos="-0.8675175148248964 -1.2538331367267728 -0.025" type="box" size="0.2696638248026586 0.17281750726869433 0.027778441016310766" quat="0.9988612556025156 -0.03078700672384246 0.026164804590234885 -0.025372332843217684" rgba="0.7584951874203689 0.21287875452746532 0.028626058052165754 0.95" /><geom pos="-0.8675175148248964 -0.9260789795831852 -0.025" type="box" size="0.31894994498354917 0.18090397201623726 0.024850629453047998" quat="0.9964822271900724 0.006965807638317787 -0.009372191836838246 -0.08298680882183822" rgba="0.017392462111286866 0.5942869596849557 0.3883205782037574 0.95" /><geom pos="-0.8675175148248964 -0.6168811527818696 -0.025" type="box" size="0.22340110038934238 0.21363548303252644 0.022902595945493345" quat="0.9995655540394174 0.0011542726743171763 0.004893350124484423 -0.02904179672514694" rgba="0.4677654164423768 0.2752395096785292 0.256995073879094 0.95" /><geom pos="-0.8675175148248964 -0.35598127782407873 -0.025" type="box" size="0.20470266253109584 0.21052917530642967 0.020665061725147232" quat="0.9992598247239115 0.03317829629277357 0.012648895044107602 0.014798945976296411" rgba="0.19520997689966957 0.249754082469409 0.5550359406309214 0.95" /><geom pos="-0.8675175148248964 -0.045536512307922994 -0.025" type="box" size="0.251367440206556 0.3141025461985023 0.02204040846746143" quat="0.998097701549267 0.011197549509502096 0.033362551223421376 -0.05062146997981536" rgba="0.3289144577305875 0.03750624519892874 0.6335792970704838 0.95" /><geom pos="-0.8675175148248964 0.2386014998272401 -0.025" type="box" size="0.1810695153437991 0.29792372919316357 0.027782710598614983" quat="0.9936546614020398 0.018072091673026997 0.02328429338146507 0.10854333262934786" rgba="0.9795480774056741 0.004181957489953835 0.0162699651043721 0.95" /><geom pos="-0.8675175148248964 0.554237371875749 -0.025" type="box" size="0.17420750433680005 0.15400399070225232 0.023326631760966544" quat="0.9982795078905106 0.009470204680223646 0.006525788311340814 -0.057495681890992904" rgba="0.7118187783354063 0.024718209273163223 0.2634630123914305 0.95" /><geom pos="-0.8675175148248964 0.8324677152705591 -0.025" type="box" size="0.19605934088566646 0.3406174768333365 0.027204515713930025" quat="0.9927296487787496 -0.03191267903957788 0.015296662197356297 -0.11504537138780158" rgba="0.4154981251783505 0.04564084156140814 0.5388610332602414 0.95" /><geom pos="-0.8675175148248964 1.173399401341392 -0.025" type="box" size="0.2931807452612923 0.3237494376215295 0.02466365767666236" quat="0.9998032876019995 -0.010652938508300307 0.01148627606106442 -0.012164146645805564" rgba="0.31927844856668386 0.32067607044972113 0.360045480983595 0.95" /><geom pos="-0.8675175148248964 1.4695007415315127 -0.025" type="box" size="0.2012474064990369 0.21525586937494923 0.026143019204471145" quat="0.9943999958398614 -0.0010892117477037228 -0.01706919630913809 0.10428856326948094" rgba="0.003283994302293647 0.9075793345700643 0.08913667112764201 0.95" /><geom pos="-0.8675175148248964 1.7372398558571103 -0.025" type="box" size="0.3188218184987729 0.2125278687840172 0.0274949698185659" quat="0.9979356518043522 -0.027578003690143987 -0.00428217941730478 -0.057840742645016534" rgba="0.6413930640036271 0.13542057324046244 0.2231863627559105 0.95" /><geom pos="-0.8675175148248964 2.0008690775820694 -0.025" type="box" size="0.2969281875369458 0.31367135889613273 0.028897132197751908" quat="0.999200295982677 -0.032087885078711346 0.007629020598047007 -0.022603853300284922" rgba="0.584272416392462 0.39768903703314085 0.018038546574397185 0.95" /><geom pos="-0.8675175148248964 2.3191623136201596 -0.025" type="box" size="0.28119207236551635 0.32461932552163675 0.02582066199702901" quat="0.9991675431586795 -0.0038269726754420336 0.03314845066145144 -0.023468174132967003" rgba="0.26667130798248484 0.02687954337566715 0.706449148641848 0.95" /><geom pos="-0.8675175148248964 2.6246264158670174 -0.025" type="box" size="0.31675826045128563 0.15113775221228543 0.024600139719222314" quat="0.9984001114162759 0.022534668220484288 -0.0011221383858814886 0.05184734378542023" rgba="0.4798786604257872 0.11393691518282668 0.40618442439138613 0.95" /><geom pos="-0.8675175148248964 2.8973291406120483 -0.025" type="box" size="0.2665096506236464 0.23559273001662864 0.02402499207965114" quat="0.9960749143949714 -0.019850656467655683 0.022840122302478692 -0.08318079804895749" rgba="0.4840941300955157 0.27311468441903697 0.24279118548544731 0.95" /><geom pos="-0.5645400825203382 -2.7346806109129407 -0.025" type="box" size="0.2852189012620068 0.21171860505892798 0.029885239184457957" quat="0.9989679593638812 -0.009781963623908006 -0.011299859946357991 -0.04289105404646087" rgba="0.8420370746198136 0.15507560961271377 0.0028873157674726424 0.95" /><geom pos="-0.5645400825203382 -2.4180990506610947 -0.025" type="box" size="0.2262693129179819 0.3165977897463062 0.02216499697065091" quat="0.9945824878805418 0.02098332727822554 -0.0002115190112940003 0.1018102648920753" rgba="0.15014688458303993 0.25908847984765504 0.590764635569305 0.95" /><geom pos="-0.5645400825203382 -2.070008028055149 -0.025" type="box" size="0.29710993802266744 0.20442016528514978 0.023959365092977056" quat="0.9949734406341485 0.030463371816581465 -0.030902794150011816 -0.09024883779823058" rgba="0.130743939429401 0.705739851411452 0.163516209159147 0.95" /><geom pos="-0.5645400825203382 -1.78961928174397 -0.025" type="box" size="0.1995462534246669 0.1537680185545427 0.029444085646892788" quat="0.9989037381456738 0.032204586650199665 0.012385806461524394 0.031635080458039776" rgba="0.9405140787311629 0.04022887694091853 0.01925704432791859 0.95" /><geom pos="-0.5645400825203382 -1.4464506835368518 -0.025" type="box" size="0.2064233017598484 0.16856045560242466 0.020374398918941817" quat="0.9990187545620187 0.010751382161719092 -0.019449345857345684 -0.038310034725735825" rgba="0.7738449145818376 0.22034108043152842 0.005814004986634008 0.95" /><geom pos="-0.5645400825203382 -1.1101924109610672 -0.025" type="box" size="0.31480202738660323 0.3238813420671242 0.02150357961906459" quat="0.9887447702975408 0.035389631111902846 -0.024951303637656304 0.14320888822209432" rgba="0.6163135144917306 0.10489946750564279 0.2787870180026267 0.95" /><geom pos="-0.5645400825203382 -0.8047503288554538 -0.025" type="box" size="0.32969411560778417 0.2437943563641087 0.021842645508792814" quat="0.9942772474556457 -0.015775771300364633 -0.02784509992878504 -0.10192414160471963" rgba="0.0634743068889918 0.09623074254558771 0.8402949505654205 0.95" /><geom pos="-0.5645400825203382 -0.46304278991349923 -0.025" type="box" size="0.19982090735799363 0.317802124354841 0.022348721068035326" quat="0.9943736515831052 0.029008931946009443 0.0283986076484427 0.09784192346976323" rgba="0.028165162447780112 0.28755307628819726 0.6842817612640226 0.95" /><geom pos="-0.5645400825203382 -0.13413341170359017 -0.025" type="box" size="0.30039486868003057 0.32195639474349885 0.02483861611404758" quat="0.998012601447642 -0.034771334079982334 0.01989076133711607 0.04864318340156363" rgba="0.2870209357060214 0.28847749190621685 0.42450157238776176 0.95" /><geom pos="-0.5645400825203382 0.11598892369012903 -0.025" type="box" size="0.31271246596871466 0.31501828851954383 0.021780125918278832" quat="0.9940774142374391 -0.02138386845664483 -0.029243823413054103 0.1024579107000626" rgba="0.3361885749126923 0.577576138524289 0.08623528656301871 0.95" /><geom pos="-0.5645400825203382 0.4165252881048609 -0.025" type="box" size="0.25262317590937033 0.20490015786806653 0.0293636715562862" quat="0.9989349842195724 0.006214312682987597 -0.013888020205821014 0.043559184047493656" rgba="0.95569925246749 0.017776799232195165 0.026523948300314844 0.95" /><geom pos="-0.5645400825203382 0.7171937875589554 -0.025" type="box" size="0.20204542330537914 0.256636598717831 0.02740234277073415" quat="0.994501894934752 -0.011666644219752728 0.007634257090894432 0.10378626355403238" rgba="0.5287698879638765 0.38111886701564485 0.09011124502047868 0.95" /><geom pos="-0.5645400825203382 1.0572823270060736 -0.025" type="box" size="0.15187316096948905 0.2787704386937464 0.02838554795980891" quat="0.9891879667821167 -0.02246894094075169 0.0075308920044031835 -0.14472594353494755" rgba="0.9986180303941757 0.0013604535940895713 2.1516011734691197e-05 0.95" /><geom pos="-0.5645400825203382 1.3735013013467592 -0.025" type="box" size="0.27511297078206787 0.3125708061757323 0.020712848684852937" quat="0.998778238550547 0.03318971674333889 0.021536511242788506 0.029608302616882517" rgba="0.872406344130656 0.012353005288357475 0.11524065058098654 0.95" /><geom pos="-0.5645400825203382 1.6855756527248333 -0.025" type="box" size="0.2110358277343492 0.26728682626018696 0.025563791471886525" quat="0.994659005895059 -0.015223789729309023 -0.03357211703281124 -0.09640856381082616" rgba="0.685353952850743 0.11780869270097234 0.1968373544482847 0.95" /><geom pos="-0.5645400825203382 2.028485761974842 -0.025" type="box" size="0.2512949114542015 0.34109073332393575 0.02796602830444305" quat="0.9982823671849633 -0.03343803204744027 0.02285194856552308 0.04233204255808068" rgba="0.9072493317685925 0.08953507991015373 0.0032155883212538067 0.95" /><geom pos="-0.5645400825203382 2.284103155103402 -0.025" type="box" size="0.2778400977616776 0.34609715311439043 0.021038654161907797" quat="0.9922434753237994 0.012583005497793362 -0.02671404831477201 -0.12075145246591178" rgba="0.6776823037004573 0.3146017791749142 0.007715917124628435 0.95" /><geom pos="-0.5645400825203382 2.5627170343280543 -0.025" type="box" size="0.23760035669501509 0.3481644790645222 0.024250029943854275" quat="0.9982331251111897 0.022457217649481755 -0.025056336935878627 -0.04897429208827379" rgba="0.9191875270576779 0.036819334397820945 0.04399313854450113 0.95" /><geom pos="-0.5645400825203382 2.831890416698073 -0.025" type="box" size="0.17416173499415752 0.1948622801631588 0.027121842059979685" quat="0.9941800250331052 0.0125429867841376 0.009410257672223175 -0.10658423128328938" rgba="0.08124155285484558 0.8169265064371168 0.10183194070803758 0.95" /><geom pos="-0.5645400825203382 3.1418585782126573 -0.025" type="box" size="0.1764505195130005 0.2239473249024416 0.02884102376274983" quat="0.9958455134460775 0.0198834300205379 -0.020903876454454903 0.0863677631359837" rgba="0.35542852290564997 0.3730124139617016 0.27155906313264844 0.95" /><geom pos="-0.24021586322847988 -2.6613437320510256 -0.025" type="box" size="0.25014454418443655 0.1875376972996324 0.02663088541634609" quat="0.9889586961993826 0.024275005160379608 -0.029557792340084328 0.1431703818813834" rgba="0.9728406009284626 0.02699326632509426 0.00016613274644315668 0.95" /><geom pos="-0.24021586322847988 -2.3301276279077743 -0.025" type="box" size="0.32043047791069124 0.3318505368681556 0.022403342033890605" quat="0.9960289316738935 -0.020879568420461108 0.004180074145300488 0.08644615590804058" rgba="0.6127141670069013 0.06786432801645495 0.3194215049766438 0.95" /><geom pos="-0.24021586322847988 -2.0535244625537947 -0.025" type="box" size="0.15425587593018925 0.33355185337759635 0.027555538236014337" quat="0.9947376506176471 -0.010528324027259957 0.02507014216913113 -0.09878081194483249" rgba="0.4414486881197046 0.31906972381473975 0.23948158806555564 0.95" /><geom pos="-0.24021586322847988 -1.7091589805751441 -0.025" type="box" size="0.2126062613948589 0.183450734759949 0.028554690597816047" quat="0.9993191492637643 -0.03202814979354112 -0.01563249996566143 -0.009542561520491695" rgba="0.027984224128126955 0.5318380157503473 0.44017776012152576 0.95" /><geom pos="-0.24021586322847988 -1.4499704762112804 -0.025" type="box" size="0.2588908976740954 0.20569226635268673 0.02273045911715878" quat="0.9971726716031403 0.013394860055102735 0.006245876134521159 0.07367652111271296" rgba="0.9266413767743171 0.02088562262679209 0.05247300059889078 0.95" /><geom pos="-0.24021586322847988 -1.1901522845563037 -0.025" type="box" size="0.1560060541582018 0.2717893457093705 0.023215274378084048" quat="0.9980903054864887 -0.009226039898265452 -0.020746710226145725 0.057447334981491724" rgba="0.6985611890111922 0.2104759116618564 0.09096289932695137 0.95" /><geom pos="-0.24021586322847988 -0.8594487718354977 -0.025" type="box" size="0.34130278918207596 0.31644662044349087 0.025607697684599823" quat="0.9950200598748312 0.03331456757623153 -0.00525750106832918 0.09379540882373913" rgba="0.19378669922457514 0.47482273923806123 0.3313905615373636 0.95" /><geom pos="-0.24021586322847988 -0.5420455821539241 -0.025" type="box" size="0.3342899262848379 0.15839222738552414 0.026748748363146307" quat="0.9968826935797452 -0.021099015475597786 -0.020660193267174397 -0.073163400695397" rgba="0.611202219135989 0.06704486819456844 0.3217529126694425 0.95" /><geom pos="-0.24021586322847988 -0.27761616340864714 -0.025" type="box" size="0.1600373630402273 0.31882933644538497 0.022046466889891994" quat="0.9953367618602751 0.018643691513511224 0.027511248387884626 0.09055536686685718" rgba="0.3123979226631941 0.12479025366961381 0.5628118236671921 0.95" /><geom pos="-0.24021586322847988 0.055017684951285784 -0.025" type="box" size="0.23408483113075176 0.15311390755387433 0.028452579383257588" quat="0.9882301756396985 0.0029160403737020723 0.03399761122142878 -0.14912001574203934" rgba="0.10306265180897778 0.22404481766496587 0.6728925305260564 0.95" /><geom pos="-0.24021586322847988 0.3062066111380082 -0.025" type="box" size="0.2954691861072451 0.34876679833573254 0.021425137674689294" quat="0.9994386041559091 -0.015431386635100209 0.023913401653820807 -0.01767761439643198" rgba="0.2606543115563804 0.1611523021798176 0.578193386263802 0.95" /><geom pos="-0.24021586322847988 0.6074494687390897 -0.025" type="box" size="0.18784633903139336 0.2183786688542541 0.0215739516947196" quat="0.9994355282885157 -0.027508686003467016 -0.01928076621685717 -0.000386061017401401" rgba="0.0007259659552775188 0.5079821722210802 0.49129186182364226 0.95" /><geom pos="-0.24021586322847988 0.9400651171899108 -0.025" type="box" size="0.18072486079474437 0.21635350520267202 0.02740387827752023" quat="0.9884940600415709 -0.007345144879034626 0.03391175430957732 -0.14722613568549614" rgba="0.4524403975424397 0.23860283285118233 0.30895676960637797 0.95" /><geom pos="-0.24021586322847988 1.2116765309511983 -0.025" type="box" size="0.3375366031013283 0.27550878509984517 0.025849417612296994" quat="0.993672709091498 0.029610685428813222 -0.02714505212090102 0.10488517845983962" rgba="0.9788309201016464 0.006740755427983784 0.014428324470369808 0.95" /><geom pos="-0.24021586322847988 1.5599098073958677 -0.025" type="box" size="0.15615440197827063 0.16870754739004765 0.025838480173230212" quat="0.9979067183154405 -0.026423047038694837 0.03263498177459737 -0.04918294511993732" rgba="0.34758949708303133 0.2962841534048246 0.35612634951214406 0.95" /><geom pos="-0.24021586322847988 1.8704731348463817 -0.025" type="box" size="0.26320092402823847 0.1934358425581838 0.028322309269882433" quat="0.9978602860302079 0.029460625482426544 -0.027886162303576916 0.05127653519763532" rgba="0.3541982979087136 0.016387768693447245 0.6294139333978391 0.95" /><geom pos="-0.24021586322847988 2.1310354457341703 -0.025" type="box" size="0.3479169691132364 0.24704841431317986 0.026680967508606566" quat="0.9902280357825669 -0.0099334521813573 0.004941239672282789 0.13901563879096937" rgba="0.1661535576628259 0.1859930068427066 0.6478534354944675 0.95" /><geom pos="-0.24021586322847988 2.4467713463011327 -0.025" type="box" size="0.26706888461284806 0.1800266737590775 0.028179915540879424" quat="0.9888437938920461 0.015672900564947263 -0.0037847479411064104 0.1480810155019475" rgba="0.6349166931129651 0.23868065916247677 0.12640264772455817 0.95" /><geom pos="-0.24021586322847988 2.7530008556515018 -0.025" type="box" size="0.22715446320310942 0.27945092283866435 0.021206172911557228" quat="0.9992976479584293 -0.007298877892680184 0.03264560328108784 0.016887917357466514" rgba="0.47599844165773086 0.2580042407645821 0.265997317577687 0.95" /><geom pos="-0.24021586322847988 3.0292020746635338 -0.025" type="box" size="0.2836468863134134 0.3470412454145971 0.022801247044754638" quat="0.9998510674582697 0.011263345314577953 0.006568746058597345 -0.011306260659515247" rgba="0.4662586009943964 0.3763899802919271 0.15735141871367647 0.95" /><geom pos="0.10048972260678601 -2.7183977477420767 -0.025" type="box" size="0.3400192128517589 0.1705424023508004 0.027129159472096966" quat="0.9948115684492213 -0.013949181290465282 -0.01079706902845673 0.10019374691726388" rgba="0.41699443147936244 0.09048334042446964 0.4925222280961679 0.95" /><geom pos="0.10048972260678601 -2.3851364988824892 -0.025" type="box" size="0.22699458305075954 0.30108631944972086 0.02457085850913711" quat="0.9929597507198714 -0.010016054299094744 0.004254709257103315 -0.11795130162802774" rgba="0.2579619547194447 0.4788593913677697 0.26317865391278555 0.95" /><geom pos="0.10048972260678601 -2.096460040619255 -0.025" type="box" size="0.16575359937207934 0.18114381333364116 0.02207584374280834" quat="0.9939048902716417 0.02288598293893619 -0.010901978045246414 -0.10728675479170488" rgba="0.27434404166659687 0.7215567976888212 0.004099160644581934 0.95" /><geom pos="0.10048972260678601 -1.8170149137888736 -0.025" type="box" size="0.19473330092727462 0.1504801711927391 0.0222095520526638" quat="0.9937189062892962 0.00022223637097237457 0.028105908821595662 0.10831779070638635" rgba="0.15616324958645245 0.5581121202446754 0.2857246301688722 0.95" /><geom pos="0.10048972260678601 -1.4722373183958124 -0.025" type="box" size="0.23498081965806733 0.25361132732349884 0.024223325733453364" quat="0.9895661028162235 -0.0025968499945823757 0.03017603663436291 0.14086018365832967" rgba="0.24568626530647764 0.01999480812264065 0.7343189265708817 0.95" /><geom pos="0.10048972260678601 -1.1643430456357362 -0.025" type="box" size="0.21631363740856496 0.2614268827250951 0.022309334270692448" quat="0.9979720101316232 0.034346631221644865 -0.028147407564155506 0.04560591370632762" rgba="0.8595326471448805 0.08943438103043908 0.05103297182468039 0.95" /><geom pos="0.10048972260678601 -0.8859642154409579 -0.025" type="box" size="0.3497814895570573 0.18771356110500625 0.02068108069063868" quat="0.9993486847229633 0.0002545749347013983 -0.012085325112060038 -0.03400127131478614" rgba="0.3594717949951155 0.3646918743261123 0.2758363306787722 0.95" /><geom pos="0.10048972260678601 -0.5610066942912169 -0.025" type="box" size="0.34447629219632936 0.19198441246732728 0.022523577549686657" quat="0.9986387253487368 0.03265729859453342 0.0032457597768995776 0.04054210312537156" rgba="0.6508982755023488 0.20512100759330876 0.14398071690434244 0.95" /><geom pos="0.10048972260678601 -0.21401331297384507 -0.025" type="box" size="0.1934615551103825 0.3479732246709851 0.021767129764457077" quat="0.9967476277283801 0.0357014883491362 0.01689654639196775 -0.07024298589558385" rgba="0.33050922629381485 0.35502870258372016 0.314462071122465 0.95" /><geom pos="0.10048972260678601 0.12625905170080554 -0.025" type="box" size="0.32304292603890566 0.19941503446354159 0.026091368972792357" quat="0.9887194244742558 -0.007212471887625459 0.020345184340497677 -0.1482159012748568" rgba="0.8172522785412294 0.15828031180266242 0.02446740965610819 0.95" /><geom pos="0.10048972260678601 0.46211462477824394 -0.025" type="box" size="0.18666190498132892 0.2600545762745169 0.022077805811023553" quat="0.9994890801333093 0.023376485547517367 -0.004182821359521499 0.021392115912002487" rgba="0.38140407791732023 0.2802814730073751 0.33831444907530467 0.95" /><geom pos="0.10048972260678601 0.7611831606158623 -0.025" type="box" size="0.3298200533997786 0.16592272713181483 0.020376549433158697" quat="0.9998984506458908 -0.012670513067205808 0.006228523988252337 0.0019370037400330891" rgba="0.5392171074577091 0.3611096063616527 0.0996732861806382 0.95" /><geom pos="0.10048972260678601 1.051485942253727 -0.025" type="box" size="0.32249883313946087 0.1766562186059376 0.023994631577261255" quat="0.9994976976168122 -0.0052114491145652106 0.030254761956201585 0.007864008888049237" rgba="0.4985944449277555 0.44751482016296384 0.053890734909280646 0.95" /><geom pos="0.10048972260678601 1.3193721889198065 -0.025" type="box" size="0.18695325014998793 0.21137971420623286 0.023980705932609453" quat="0.9986311456454671 -0.03195812628743899 0.018088878720976954 0.037246551218010626" rgba="0.84949475911259 0.03402528847797837 0.11647995240943165 0.95" /><geom pos="0.10048972260678601 1.5926571905782767 -0.025" type="box" size="0.28302627516329515 0.18606098736921706 0.028830731585331802" quat="0.9947987171084388 0.0024484101990040375 -0.02151253150305556 0.09953255103347683" rgba="0.8460165980076191 0.14500686512203195 0.008976536870348967 0.95" /><geom pos="0.10048972260678601 1.8994831356751787 -0.025" type="box" size="0.24218486682747292 0.20781137704091024 0.023454271411968437" quat="0.9989131807749295 -0.006733016255407901 -0.03397261608305441 0.031192709447736548" rgba="0.16226869819826217 0.2790765911168745 0.5586547106848634 0.95" /><geom pos="0.10048972260678601 2.215876896360337 -0.025" type="box" size="0.21983282359586473 0.2309949905166838 0.029924721864305236" quat="0.9993636510300432 -0.023420930165025056 0.0230802297994406 0.013822301635844393" rgba="0.9733057272512569 0.018205889190279125 0.008488383558464017 0.95" /><geom pos="0.10048972260678601 2.5365699016649277 -0.025" type="box" size="0.29730955143158483 0.3177850652555829 0.026648115530923555" quat="0.9987943436831141 -0.017034262772951968 -0.02930967601679725 -0.03550543353051393" rgba="0.5476008019644506 0.3276434718998952 0.12475572613565422 0.95" /><geom pos="0.10048972260678601 2.8785934382952405 -0.025" type="box" size="0.17984951200673832 0.29032244051788914 0.022649597433062288" quat="0.9981737614220014 -0.03272132933086661 -0.031805899471454416 -0.0395833471839588" rgba="0.7552905726508319 0.018640276667557232 0.22606915068161088 0.95" /><geom pos="0.10048972260678601 3.1420261912066882 -0.025" type="box" size="0.3259937290068373 0.18213715560859955 0.025349995068183258" quat="0.9886075464259502 -0.008325737462163226 -0.019772042617555628 -0.148979419975055" rgba="0.6206508066537981 0.12261471597667564 0.25673447736952626 0.95" /><geom pos="0.4332415553037423 -2.7062985721652426 -0.025" type="box" size="0.29235351701454304 0.19174596109059547 0.022224012672612654" quat="0.9948544651767551 0.016510385238973243 0.01160515238114068 -0.09928404068803728" rgba="0.8059136400727147 0.1800703370122224 0.014016022915062903 0.95" /><geom pos="0.4332415553037423 -2.4081117374682757 -0.025" type="box" size="0.34899226128645605 0.24401964207601495 0.0267586532688309" quat="0.9942417683381076 0.009065356921650057 -0.026090680166313024 0.10353937320775651" rgba="0.8802213943562668 0.09422473438264058 0.02555387126109264 0.95" /><geom pos="0.4332415553037423 -2.064791969802163 -0.025" type="box" size="0.19519957613623792 0.1718216093859503 0.02449893843252938" quat="0.9898261215392666 0.01903310322771117 0.0027731097592732686 0.14097623899905828" rgba="0.07455455672293287 0.6463787883483402 0.27906665492872695 0.95" /><geom pos="0.4332415553037423 -1.7371596522438952 -0.025" type="box" size="0.27658574314807555 0.3431700845693154 0.021418893948822317" quat="0.99846572599148 -0.028441031495176704 -0.03441167988754291 0.032758785617208026" rgba="0.100550081241087 0.07499935893938404 0.824450559819529 0.95" /><geom pos="0.4332415553037423 -1.4385271231059424 -0.025" type="box" size="0.1966722663020935 0.31951455422433506 0.02400127412473782" quat="0.9969832958945165 0.023062318969183152 0.001370640861079845 0.07409830291376794" rgba="0.32129258627356305 0.3557767111951602 0.32293070253127676 0.95" /><geom pos="0.4332415553037423 -1.1838945603867423 -0.025" type="box" size="0.24974420427169125 0.3094577384321505 0.02441291751237307" quat="0.9994735427730923 0.013485065378965077 -0.019225776352924523 0.02238659938346932" rgba="0.9260218890182023 0.0576410604361772 0.01633705054562054 0.95" /><geom pos="0.4332415553037423 -0.8472483765199779 -0.025" type="box" size="0.31909317632283696 0.15874411944335326 0.02607086258201829" quat="0.9997500258094135 -0.00428424009532244 0.0005456687511293588 0.021937033220028226" rgba="0.3381416544101221 0.049480343907023536 0.6123780016828544 0.95" /><geom pos="0.4332415553037423 -0.543655601243997 -0.025" type="box" size="0.2893492750106253 0.19588323547364714 0.020149276592415798" quat="0.9902197816401039 -0.010078078764690569 0.020929744865809275 0.13756875428995413" rgba="0.12650639319422885 0.7786925056416398 0.09480110116413132 0.95" /><geom pos="0.4332415553037423 -0.292473906325871 -0.025" type="box" size="0.2823062670098281 0.22544352779928198 0.028166047955354292" quat="0.9964027264958728 -0.02849360733682901 0.03072628202120748 -0.07365878471491834" rgba="0.5047172391799973 0.014971027922429133 0.4803117328975735 0.95" /><geom pos="0.4332415553037423 0.03519715291620962 -0.025" type="box" size="0.22153890801416748 0.17386956967109624 0.026406009189283798" quat="0.9977937388336221 -0.016975646801980233 -0.0008804812405569841 -0.06417715257676404" rgba="0.08090363824110414 0.4195796378078392 0.4995167239510567 0.95" /><geom pos="0.4332415553037423 0.32949594378890135 -0.025" type="box" size="0.3458593632494473 0.16997944682456476 0.028069566761094032" quat="0.9890069019010512 0.01829520610533272 -0.009330920714726066 -0.14643622278747628" rgba="0.8379698606821779 0.10325104639037852 0.058779092927443544 0.95" /><geom pos="0.4332415553037423 0.5977554012539912 -0.025" type="box" size="0.28328254350644144 0.27466402644148025 0.02518935775546747" quat="0.9994403768154398 -0.03288651925147118 0.006115031076952913 -0.00012820866680636383" rgba="0.021927518682833047 0.395946741972472 0.582125739344695 0.95" /><geom pos="0.4332415553037423 0.9069212353784768 -0.025" type="box" size="0.2911598484485848 0.2841400454339699 0.02822696500627435" quat="0.994277540528417 0.02756047784371323 0.027229439768346467 0.09955475916142872" rgba="0.6264303412196546 0.3061321483027454 0.06743751047760005 0.95" /><geom pos="0.4332415553037423 1.2065451464351327 -0.025" type="box" size="0.2209581070745339 0.20897683643668566 0.026778166874255795" quat="0.998830510832753 0.033732563939694496 -0.03389516295343892 0.007130405878759968" rgba="0.9386920013463319 0.011449826160798314 0.04985817249286978 0.95" /><geom pos="0.4332415553037423 1.473021486223895 -0.025" type="box" size="0.34916354027371155 0.2186154946014857 0.023106149019574293" quat="0.9994137989251797 -0.02429879962155738 0.01494983632825788 -0.018924303121915856" rgba="0.08298000632733471 0.8693065982507522 0.04771339542191311 0.95" /><geom pos="0.4332415553037423 1.8084936970147485 -0.025" type="box" size="0.18640867812317774 0.27797494732419803 0.024843680509756712" quat="0.9887878929114227 0.0024735744233971876 0.03277549024801159 -0.1456645169571627" rgba="0.29908880943771776 0.43689682949824904 0.2640143610640332 0.95" /><geom pos="0.4332415553037423 2.071168791445075 -0.025" type="box" size="0.2099733689347019 0.24644745942789031 0.025877171056362783" quat="0.9956116185385057 0.01892844872029868 0.023131379916693017 -0.08868008865201764" rgba="0.6586849193503914 0.11242117150521301 0.22889390914439556 0.95" /><geom pos="0.4332415553037423 2.403881917595819 -0.025" type="box" size="0.27211213353507335 0.1719537991738804 0.029632479974118716" quat="0.9885416235510325 0.025892605820913323 -0.030684083710819397 0.14551123144870623" rgba="0.3938378250474468 0.020099819504322734 0.5860623554482305 0.95" /><geom pos="0.4332415553037423 2.736896921379337 -0.025" type="box" size="0.17048668090239044 0.3431729170445582 0.023299777730823267" quat="0.9996380187251772 0.022380507992549804 -0.002886765546216384 -0.014649606338698967" rgba="0.2775135554084037 0.41648369063290475 0.30600275395869153 0.95" /><geom pos="0.4332415553037423 3.040850828373503 -0.025" type="box" size="0.15199278600452623 0.28840415695308574 0.020092419999062118" quat="0.9946555701827042 -0.011380990784114193 -0.027592662602539748 -0.09884034967458294" rgba="0.011450629551170266 0.478900030901683 0.5096493395471468 0.95" /><geom pos="0.772067225393485 -2.7270097919586562 -0.025" type="box" size="0.20045140910059844 0.25006133128522096 0.025865059463835566" quat="0.9935898980383469 0.026077920269193294 0.015065172252596232 -0.10895915370257177" rgba="0.07526425351026711 0.6517112317906348 0.27302451469909805 0.95" /><geom pos="0.772067225393485 -2.4373797559679886 -0.025" type="box" size="0.2249039763214054 0.27354719809460404 0.029069216913113458" quat="0.9927795893516838 -0.0007571178665882611 -0.02768223213788446 -0.11671250045775833" rgba="0.6861717487412669 0.23613577417177264 0.0776924770869605 0.95" /><geom pos="0.772067225393485 -2.1644550497252606 -0.025" type="box" size="0.2069688807789497 0.22809298771538916 0.02851663172199938" quat="0.9899361305544322 -0.014028773596022694 0.03401676640549161 -0.1366473949170786" rgba="0.032848854101445446 0.7862148571439508 0.18093628875460377 0.95" /><geom pos="0.772067225393485 -1.8228650301579217 -0.025" type="box" size="0.20783148263417323 0.3226525888868413 0.02822448643683259" quat="0.9987862966325671 0.015572265404140745 -0.0198922172553892 0.042281649705860895" rgba="0.7834603443915055 0.05418900410122616 0.16235065150726838 0.95" /><geom pos="0.772067225393485 -1.4733138217123074 -0.025" type="box" size="0.17180291463220643 0.2944653300970858 0.027090350189381485" quat="0.9991218390244782 -0.028215448210910193 0.028502339096947514 -0.012126662055349909" rgba="0.5689945428783012 0.2641521240986568 0.166853333023042 0.95" /><geom pos="0.772067225393485 -1.1940732508320098 -0.025" type="box" size="0.1799587894967027 0.21149891272052987 0.022770737368591497" quat="0.9937311756212462 0.02665062522015784 0.037291944325641695 0.10196766969095435" rgba="0.03525340524841514 0.31235760715005273 0.6523889876015321 0.95" /><geom pos="0.772067225393485 -0.9155713523044682 -0.025" type="box" size="0.21633895365402683 0.280579371392478 0.02581119717842012" quat="0.9961842190701499 -0.004398215482829723 0.03434908924836584 0.08011115680084958" rgba="0.7355472796929987 0.011199520245250347 0.25325320006175095 0.95" /><geom pos="0.772067225393485 -0.6489742402298337 -0.025" type="box" size="0.3312451445141277 0.3485804354229022 0.02458909115001357" quat="0.9975294574049214 -0.015337588399342418 0.01625062131085836 -0.06660073046556224" rgba="0.4685534205981443 0.1461672666469726 0.3852793127548831 0.95" /><geom pos="0.772067225393485 -0.38473304863916136 -0.025" type="box" size="0.34423976760037633 0.25890120923850307 0.029781576996077815" quat="0.9950254615351474 -0.03202437715869627 -0.007664512547985577 -0.0940214093266332" rgba="0.08902457890947835 0.8607292648340642 0.05024615625645745 0.95" /><geom pos="0.772067225393485 -0.03522843463645309 -0.025" type="box" size="0.26562997433510427 0.21040126210207935 0.028624026978993754" quat="0.9990811377871921 -0.01901137490398241 -0.02575753579047416 -0.028495562674080748" rgba="0.022002573324391483 0.2259131271951989 0.7520842994804096 0.95" /><geom pos="0.772067225393485 0.30073414813197186 -0.025" type="box" size="0.2746314729189017 0.22049994494027236 0.024347913077856928" quat="0.9923945483979504 0.01598883580637543 0.023534723559114245 -0.11976449484960429" rgba="0.24912248985494811 0.15266172709091963 0.5982157830541323 0.95" /><geom pos="0.772067225393485 0.5753171457601969 -0.025" type="box" size="0.32105984131434706 0.3398754685039892 0.027983985436702368" quat="0.9987797536360903 0.025597550129083702 -0.028314088569938726 -0.03133818026742524" rgba="0.1525979792716441 0.6514152655578155 0.19598675517054043 0.95" /><geom pos="0.772067225393485 0.845254216798438 -0.025" type="box" size="0.332834678781524 0.2753453766005389 0.02330328789300604" quat="0.9958618019652883 -0.028743061483436978 0.006727851495388373 0.08595256725231809" rgba="0.8121192750663567 0.15765416816140135 0.030226556772241925 0.95" /><geom pos="0.772067225393485 1.1042158426920405 -0.025" type="box" size="0.17295890631387473 0.17593651728634105 0.02858747593417495" quat="0.9936815706860957 0.02723425681909134 -0.0020503888889817383 0.10886242345148038" rgba="0.7948398381441129 0.11282210155045 0.09233806030543715 0.95" /><geom pos="0.772067225393485 1.4136886928884342 -0.025" type="box" size="0.16764000708999272 0.30106708408013005 0.023262674561905977" quat="0.9956758610317896 0.027818434006191863 -0.03024107021999643 0.08331381734140332" rgba="0.8140294964492227 0.1807101395303822 0.005260364020395064 0.95" /><geom pos="0.772067225393485 1.6733915233451917 -0.025" type="box" size="0.20787986834863145 0.3176170995376115 0.029638434022955684" quat="0.9918909989972258 -0.016823113755012283 0.026714643310330966 -0.12310790707616213" rgba="0.014687723413642995 0.672176521996744 0.31313575458961296 0.95" /><geom pos="0.772067225393485 2.0194066606793095 -0.025" type="box" size="0.15192707618283616 0.30905930054614233 0.02719913246295572" quat="0.9995992824136449 -0.00930928323609846 -0.011917981853813693 0.0239285091948565" rgba="0.5371943295783919 0.2065341090140102 0.25627156140759794 0.95" /><geom pos="0.772067225393485 2.3436504444896915 -0.025" type="box" size="0.16034865990254188 0.31734242448644817 0.025955708819218878" quat="0.9905460017745812 0.007447100077412674 0.0026317532035639085 0.13695339697832926" rgba="0.2223283952411359 0.5131797866201913 0.26449181813867284 0.95" /><geom pos="0.772067225393485 2.642344887423743 -0.025" type="box" size="0.28255740370478055 0.17755878414841572 0.021662218021691673" quat="0.9980638628022787 0.03101070473537667 -0.03376180814534485 -0.04203572612393773" rgba="0.5362521859469532 0.05668296778334531 0.40706484626970146 0.95" /><geom pos="0.772067225393485 2.954913485910253 -0.025" type="box" size="0.30909296567262906 0.2099503557476739 0.029976934932570667" quat="0.9938190135220363 0.027994482314619144 -0.03641172776285652 -0.10106563908345159" rgba="0.8009542739432731 0.11822267895880803 0.08082304709791885 0.95" /><geom pos="1.1137621053128708 -2.7188851475903326 -0.025" type="box" size="0.22120764794256348 0.18671375755180525 0.020927657961521063" quat="0.9900129409089803 -0.002206371459815352 0.017114091677355607 -0.13991646301916155" rgba="0.8898762245566333 0.06380952036353801 0.0463142550798287 0.95" /><geom pos="1.1137621053128708 -2.4126148256679487 -0.025" type="box" size="0.2058091054622591 0.25096492408512205 0.02030331497976405" quat="0.9986567551712544 0.0133858168069169 0.0004464478185323813 -0.0500530313125817" rgba="0.5430997111178711 0.36980568469886854 0.08709460418326032 0.95" /><geom pos="1.1137621053128708 -2.093781759168225 -0.025" type="box" size="0.1877138093362011 0.18051724426608046 0.025805079854123326" quat="0.9965089159310138 -0.009488810924293456 0.013870915681717113 -0.081777384620626" rgba="0.6148119929259446 0.1525255133977173 0.23266249367633812 0.95" /><geom pos="1.1137621053128708 -1.8350944167311058 -0.025" type="box" size="0.3491096776415582 0.2924469169972409 0.026893144647051843" quat="0.9911548857251455 -0.03230792346245134 -0.030516551268649852 -0.12504771362718295" rgba="0.37229362298153235 0.12536737226088066 0.502339004757587 0.95" /><geom pos="1.1137621053128708 -1.5529633158930993 -0.025" type="box" size="0.28602202792116577 0.30596084364086196 0.027626856997470448" quat="0.9977663484660824 -0.013788895615098102 0.023080890272556057 -0.061151064836209364" rgba="0.8603386502783659 0.08517874238276363 0.0544826073388705 0.95" /><geom pos="1.1137621053128708 -1.2116065949563253 -0.025" type="box" size="0.25079877154088576 0.21259419720679462 0.027364504240998712" quat="0.9908539515057485 -0.015052216120428787 -0.03419274819108225 0.12966392538577978" rgba="0.17272082523585597 0.11722621520970984 0.7100529595544341 0.95" /><geom pos="1.1137621053128708 -0.8964023585180536 -0.025" type="box" size="0.26244334281571474 0.23547457640111075 0.029576553845138638" quat="0.9990186322571092 0.033633786623845474 0.002793405775798891 -0.028683404342034258" rgba="0.01863636744119046 0.6109524105383064 0.37041122202050314 0.95" /><geom pos="1.1137621053128708 -0.6192761668128992 -0.025" type="box" size="0.208218455780898 0.21573302402455768 0.020667638306845034" quat="0.9951440094921936 0.03555636975097717 0.01883883651122553 -0.08982896626832507" rgba="0.2771814345142929 0.26510709576444574 0.45771146972126137 0.95" /><geom pos="1.1137621053128708 -0.3422679913905844 -0.025" type="box" size="0.31987528175711627 0.19356349341728118 0.0215046354610375" quat="0.9897448859286145 0.02598876913938156 -0.010258087144124505 0.14008717394864187" rgba="0.6512081316412563 0.10919899103965591 0.23959287731908774 0.95" /><geom pos="1.1137621053128708 -0.056902586263661625 -0.025" type="box" size="0.2498400577629378 0.17575196930307158 0.02358220213760514" quat="0.99908230499968 0.0007404139818338569 0.02502060229556309 -0.03475584964332338" rgba="0.5688637727654131 0.05428956391429142 0.3768466633202955 0.95" /><geom pos="1.1137621053128708 0.22991865817065138 -0.025" type="box" size="0.25348045151875415 0.15426000151640407 0.02750656921927827" quat="0.9921687535039498 0.021810372730426245 -0.005716613731916051 0.12285272703207778" rgba="0.5405685021979726 0.01610873878796876 0.44332275901405865 0.95" /><geom pos="1.1137621053128708 0.5398703969417249 -0.025" type="box" size="0.2552052758288428 0.29509464376907657 0.024413596656582714" quat="0.9958131354464268 0.01770080692678345 0.0062259839925212 -0.08946573550707833" rgba="0.06945500604135146 0.06981450545236038 0.8607304885062882 0.95" /><geom pos="1.1137621053128708 0.8432366098645945 -0.025" type="box" size="0.1675702556279562 0.25758595651781957 0.023893351649856762" quat="0.9892361111637392 -0.0022071349459466885 0.013233303313763694 0.1457117860997468" rgba="0.9086436783006558 0.0076479213266855105 0.08370840037265864 0.95" /><geom pos="1.1137621053128708 1.1004780052512118 -0.025" type="box" size="0.17182588372856322 0.339604554332676 0.028095670762102957" quat="0.998139963725707 -0.005172900358226737 0.0010969981481878924 0.06073426142294758" rgba="0.3819642996040219 0.6007916915847563 0.01724400881122179 0.95" /><geom pos="1.1137621053128708 1.3925957954326318 -0.025" type="box" size="0.3156024445728324 0.15689683420984435 0.026768832522491844" quat="0.997694682780985 -0.010318673144058077 0.03001906708219165 0.0599808348275552" rgba="0.9717529387459489 0.007160054322433523 0.021087006931617552 0.95" /><geom pos="1.1137621053128708 1.6676354193369027 -0.025" type="box" size="0.17404183376851473 0.28789016289874275 0.02183760728214479" quat="0.9978425481790231 0.013089219847540662 0.015033700998671552 -0.06255325092798437" rgba="0.522306115775384 0.06711559479306711 0.4105782894315489 0.95" /><geom pos="1.1137621053128708 1.9449816659747405 -0.025" type="box" size="0.3376347350732129 0.2290114773047503 0.027937792204106027" quat="0.9991838099258711 0.030064248238672986 -0.004412209652090472 0.026615547446003203" rgba="0.8644555247217611 0.03520589114652729 0.10033858413171158 0.95" /><geom pos="1.1137621053128708 2.228550670680975 -0.025" type="box" size="0.1731928708568949 0.24248065545398392 0.025756534243871265" quat="0.9996447154331721 -0.006802000201277672 -0.025462861220660712 0.003977235000838012" rgba="0.3041972352930471 0.6222212017289628 0.07358156297799012 0.95" /><geom pos="1.1137621053128708 2.4989415199280556 -0.025" type="box" size="0.15048542468480747 0.33597749003063665 0.02558735325787929" quat="0.990906764158493 0.010282696378577294 -0.01565227261868263 -0.13324059915056344" rgba="0.9290024735319976 0.05415646163409258 0.016841064833909812 0.95" /><geom pos="1.1137621053128708 2.764651020854683 -0.025" type="box" size="0.2412446677450269 0.24879514534741845 0.029031600046941154" quat="0.9969269023953169 -0.015179529482054421 -0.027764706974192928 0.0716620835018008" rgba="0.3123612123765497 0.019436731081301697 0.6682020565421486 0.95" /><geom pos="1.3949769656554647 -2.6692320877296805 -0.025" type="box" size="0.3263901409701563 0.15934086607375375 0.029635782970090296" quat="0.9956237137196982 0.02083445471226584 -0.009194011668472064 0.090635623930545" rgba="0.5891042218425144 0.08642830198531251 0.3244674761721731 0.95" /><geom pos="1.3949769656554647 -2.324487643322958 -0.025" type="box" size="0.22822762047676795 0.30661782781084124 0.022097255067799308" quat="0.9989974907433395 0.0185445445881461 -0.016202273207622526 0.03738448471538438" rgba="0.7869809117959626 0.08133817639358452 0.13168091181045283 0.95" /><geom pos="1.3949769656554647 -2.0179218187480434 -0.025" type="box" size="0.30279862010552916 0.22911688983427586 0.027520731979739095" quat="0.9884474380710413 -0.018906645926401986 -0.029665278740907707 0.1474251408269049" rgba="0.9016889346222219 0.009608825918085874 0.08870223945969224 0.95" /><geom pos="1.3949769656554647 -1.7223637386708472 -0.025" type="box" size="0.16914129635780337 0.33541116065694965 0.0200004402276212" quat="0.996775167938904 -0.025204301335700254 0.002581719889519457 0.07614028169741198" rgba="0.1487766935975411 0.5267677711784572 0.3244555352240017 0.95" /><geom pos="1.3949769656554647 -1.4397237367096878 -0.025" type="box" size="0.2679530760744592 0.18249453234925644 0.02955604662769" quat="0.9938356036665156 -0.028902142196278468 0.001142009931044281 -0.10702408548824922" rgba="0.5081742818898832 0.414535473403941 0.07729024470617579 0.95" /><geom pos="1.3949769656554647 -1.0947510673028211 -0.025" type="box" size="0.261519883496488 0.19518294716364265 0.02320967147410125" quat="0.9955511466853318 -0.03405882631670698 0.007935243731069063 0.08749252876890717" rgba="0.005258906832666499 0.24402015085116846 0.750720942316165 0.95" /><geom pos="1.3949769656554647 -0.754388165001064 -0.025" type="box" size="0.22583827017756303 0.29705400486933936 0.02247731267079952" quat="0.9987054290987752 -0.014966478673917863 -0.01809559402816935 -0.045122276998199574" rgba="0.23311246674074326 0.33923491802061456 0.4276526152386422 0.95" /><geom pos="1.3949769656554647 -0.47788271333644605 -0.025" type="box" size="0.22210541006552958 0.20788162019032944 0.026028140872415315" quat="0.9995792363156313 -0.0038561573158989166 -0.01623869298727009 -0.023723094812428958" rgba="0.18474593838185727 0.606219055257456 0.20903500636068673 0.95" /><geom pos="1.3949769656554647 -0.20236166026372882 -0.025" type="box" size="0.31772222007241 0.22610252781398793 0.024503088797565544" quat="0.9928792204067086 -0.01491298280451558 0.008610323194894205 -0.11787416579945839" rgba="0.517996385498745 0.41083330965209086 0.07117030484916409 0.95" /><geom pos="1.3949769656554647 0.05031592571719257 -0.025" type="box" size="0.15698112224795696 0.15855733995536392 0.026745031266460207" quat="0.9929150058046967 -0.02907118033687588 -0.03146410206235568 -0.11083622153019201" rgba="0.2136548921689856 0.11510531915442851 0.671239788676586 0.95" /><geom pos="1.3949769656554647 0.34920988367854866 -0.025" type="box" size="0.33273137556144966 0.2592262629844362 0.028322736113811465" quat="0.9963676511983128 0.029573600983814185 0.008747591096257966 -0.079374967215235" rgba="0.09848967471149306 0.5736904260349611 0.3278198992535458 0.95" /><geom pos="1.3949769656554647 0.6665783805796073 -0.025" type="box" size="0.16046321863248497 0.2830323329056847 0.021423380803068708" quat="0.9885924028133198 0.020363390308641188 -0.011941312070892381 0.14875415456702537" rgba="0.3745314513023764 0.22659914219577681 0.39886940650184677 0.95" /><geom pos="1.3949769656554647 1.0086498377239153 -0.025" type="box" size="0.34332610147042625 0.32946521155348557 0.022804298714608418" quat="0.9967487164423243 -0.02090596923777682 -0.007349461365730534 0.07746561907350906" rgba="0.038673228816494265 0.6080454506201485 0.35328132056335726 0.95" /><geom pos="1.3949769656554647 1.3469515893955801 -0.025" type="box" size="0.1588043493974774 0.28478714554168566 0.023391295050277105" quat="0.9982669151761574 0.0015302863458110723 -0.02803621411894876 0.05171842018328831" rgba="0.7122966010367305 0.2681795728979696 0.019523826065299843 0.95" /><geom pos="1.3949769656554647 1.6907291803701723 -0.025" type="box" size="0.3481568841399878 0.18533886121746623 0.029584132862010868" quat="0.9978239327311244 -0.02745681005546524 -0.010192055255498085 0.05907321609866585" rgba="0.6093459366416917 0.10107508624482137 0.28957897711348696 0.95" /><geom pos="1.3949769656554647 1.997059908171681 -0.025" type="box" size="0.2712533227042251 0.15753903341906836 0.02008742362083779" quat="0.9919867080104369 0.00028859170609894856 -0.011805119042598785 -0.12578921658804304" rgba="0.9540598769833025 0.04386360799669083 0.002076515020006643 0.95" /><geom pos="1.3949769656554647 2.2579760709052135 -0.025" type="box" size="0.1827376936478986 0.3137664995479815 0.021194116523697567" quat="0.9995493127443584 -0.016519955992172302 -0.008457704801695111 0.023595119745082972" rgba="0.262602509215179 0.2272635179343462 0.5101339728504748 0.95" /><geom pos="1.3949769656554647 2.5775287328854546 -0.025" type="box" size="0.3054512868883588 0.3069266447146485 0.028157936928908438" quat="0.9981213035428673 0.010385290010706 -0.031583486173814464 0.05146350713262327" rgba="0.9560439427106954 0.002626333356444072 0.04132972393286056 0.95" /><geom pos="1.3949769656554647 2.9272166526901264 -0.025" type="box" size="0.20313210109421603 0.1657290392366783 0.027042332266302618" quat="0.997372287188341 0.03588882779096004 -0.02336617061319767 0.05843402142042925" rgba="0.8427056383953379 0.04814781681845815 0.109146544786204 0.95" /><geom pos="1.3949769656554647 3.227801146263097 -0.025" type="box" size="0.2551953505791664 0.3140291993234854 0.02687814425524451" quat="0.9892126501782912 0.03694708725295888 0.02068345425698125 -0.1402335202109793" rgba="0.9021622320690676 0.0387972530509499 0.05904051487998245 0.95" /><geom pos="1.6501686493488599 -2.6765331993303305 -0.025" type="box" size="0.19974249225204205 0.200036050307714 0.02185004815450855" quat="0.9992704435848494 0.032810271981569945 -0.0174932544721379 -0.008720818666081766" rgba="0.15388414137882367 0.1439986572905582 0.7021172013306182 0.95" /><geom pos="1.6501686493488599 -2.4116752839699873 -0.025" type="box" size="0.1815916348114507 0.24255783331969288 0.021365934431404082" quat="0.9901380979774924 0.005518971626993952 0.033936366511390925 -0.1358102018027324" rgba="0.3347300677563939 0.3156005954070201 0.34966933683658596 0.95" /><geom pos="1.6501686493488599 -2.1460906778556437 -0.025" type="box" size="0.337273806017084 0.21440117794827582 0.029878043485136292" quat="0.9996923528244821 -0.0049150361191491404 0.02424669878581529 0.0017719261239419939" rgba="0.857147713470269 0.08143331331013809 0.06141897321959294 0.95" /><geom pos="1.6501686493488599 -1.8171511986798399 -0.025" type="box" size="0.2677397437680069 0.20883199111709033 0.024683413054398144" quat="0.9973982833648273 -0.02547175448390194 -0.009052199438682443 0.06682747750536275" rgba="0.7191684773611379 0.19775302553759888 0.08307849710126325 0.95" /><geom pos="1.6501686493488599 -1.5352116220569803 -0.025" type="box" size="0.17523894906762555 0.3436441158146188 0.020224112132158415" quat="0.9901554835912659 -0.027324135111236138 -0.0040545517072908205 0.13721906050189236" rgba="0.1524264296347433 0.03389895817810051 0.8136746121871562 0.95" /><geom pos="1.6501686493488599 -1.1928871518380395 -0.025" type="box" size="0.22755041169649196 0.32395043499450205 0.025624397224507288" quat="0.9993143767695899 -0.012097127214222046 -0.022140634768096645 0.027096645305915917" rgba="0.17494199281839606 0.6345130947941774 0.19054491238742655 0.95" /><geom pos="1.6501686493488599 -0.8917954911742378 -0.025" type="box" size="0.3431478652633307 0.2875234397763707 0.027453462590251325" quat="0.9976110254786781 -0.006681201193871637 0.02409807287230339 0.06439632192779682" rgba="0.035238289013804436 0.7846527006596773 0.18010901032651827 0.95" /><geom pos="1.6501686493488599 -0.6174242030732975 -0.025" type="box" size="0.18900085576015527 0.2696948685112472 0.028650449669845153" quat="0.9908557944401248 -0.020908784227569525 0.017299801154775044 0.1321678260642862" rgba="0.16256567230164776 0.562268021166706 0.2751663065316462 0.95" /><geom pos="1.6501686493488599 -0.29297093348576686 -0.025" type="box" size="0.32563199341252036 0.2948944329158796 0.024595356703583912" quat="0.9931790397475811 0.00822186766874141 -0.0013381851329535594 -0.11630135493045772" rgba="0.7249262545505445 0.06289722562291374 0.2121765198265418 0.95" /><geom pos="1.6501686493488599 0.006141969247690948 -0.025" type="box" size="0.30862536940758334 0.24949744416801403 0.02168797096732457" quat="0.9982033334692834 0.02479179831050106 0.013927623195956269 0.05273986252781999" rgba="0.41453086403926387 0.36818589821464626 0.21728323774608987 0.95" /><geom pos="1.6501686493488599 0.28658719133315147 -0.025" type="box" size="0.18616101695261472 0.3200569481285347 0.02576482478922554" quat="0.9915606501520561 -0.013640584041181259 -0.007201782726386176 0.128722748038602" rgba="0.3482815797948565 0.5591077746045676 0.09261064560057586 0.95" /><geom pos="1.6501686493488599 0.6131280942947028 -0.025" type="box" size="0.27960078490015805 0.2620079067911203 0.020514182853029642" quat="0.9922888879158301 0.026586165704924686 0.0317593607335561 0.116821580701819" rgba="0.04448374416387879 0.5417676353685879 0.41374862046753336 0.95" /><geom pos="1.6501686493488599 0.895393273848248 -0.025" type="box" size="0.26510600271332213 0.21864820314523822 0.02067816573034487" quat="0.9984175213705391 0.0305598918935405 0.026518749387349144 -0.03905511437309133" rgba="0.8127923261984895 0.12267519843335718 0.0645324753681533 0.95" /><geom pos="1.6501686493488599 1.1945375861477414 -0.025" type="box" size="0.18489115482566984 0.20318141647446314 0.022308502534853406" quat="0.999496492330029 -0.017533773637062256 -0.007925157519829643 -0.025229357508632876" rgba="0.2948731675442381 0.2015518817590633 0.5035749506966987 0.95" /><geom pos="1.6501686493488599 1.5383852953466972 -0.025" type="box" size="0.23653481123580639 0.17858510455098042 0.029020751716797074" quat="0.9942123101442419 -0.00383019671044289 -0.029028685766416727 -0.10336608415473421" rgba="0.15615771113108612 0.40713833045580866 0.4367039584131052 0.95" /><geom pos="1.6501686493488599 1.7916497535754612 -0.025" type="box" size="0.28685040634898806 0.2981729936812143 0.02331670331706432" quat="0.9994146311893446 -0.004522683129742808 -0.03329957149352099 -0.006409277675551703" rgba="0.9753157893485435 0.006903905990902918 0.017780304660553622 0.95" /><geom pos="1.6501686493488599 2.1112773499067448 -0.025" type="box" size="0.16458269150612267 0.3008705199369148 0.028663198107729028" quat="0.9999239895282996 -2.6112749568655175e-05 -0.011990625917230699 -0.002870430986154611" rgba="0.500978237624919 0.12035725630363152 0.37866450607144947 0.95" /><geom pos="1.6501686493488599 2.414226201451001 -0.025" type="box" size="0.22493916552462337 0.19127884137656465 0.022670861036047398" quat="0.9997172782894519 -0.022225764651675497 -0.006410522853799848 0.005503096575559312" rgba="0.2517742013219816 0.6602547687539382 0.08797102992408024 0.95" /><geom pos="1.6501686493488599 2.683551777955767 -0.025" type="box" size="0.26944885323531 0.32904077680637256 0.027702534205219155" quat="0.991296432897513 -0.030492694988410778 0.005865475858622523 -0.12793425604568148" rgba="0.5549109522504376 0.06134691833662102 0.38374212941294134 0.95" /><geom pos="1.6501686493488599 3.0085836815522393 -0.025" type="box" size="0.34969411206683665 0.26322255243889536 0.020377375296646325" quat="0.99886515133314 -0.007379648740719338 0.018808145512030063 0.04313008113932957" rgba="0.8353049363208682 0.11680569171706388 0.0478893719620679 0.95" /><geom pos="1.9542218575402357 -2.665401015878844 -0.025" type="box" size="0.26482878456263437 0.20904779948875923 0.025814453907057954" quat="0.9925586111066131 -0.017398096458584537 -0.0372094451227411 0.11463056726452409" rgba="0.10730184110837071 0.21825427082636145 0.6744438880652679 0.95" /><geom pos="1.9542218575402357 -2.3375581973448396 -0.025" type="box" size="0.17251051114064675 0.21357696881480137 0.029922165244058864" quat="0.9989277433441062 -0.029142489732233393 -0.007379553938454394 -0.035208252630993066" rgba="0.5058979721249398 0.27925786164694366 0.21484416622811653 0.95" /><geom pos="1.9542218575402357 -2.062145829272841 -0.025" type="box" size="0.3386201902299071 0.16021459189605858 0.02412406773348019" quat="0.9961612972728192 -0.005193620026803091 -0.001412583394641413 -0.08737105204187735" rgba="0.8554585200029335 0.09035796057399191 0.05418351942307455 0.95" /><geom pos="1.9542218575402357 -1.7775726714360827 -0.025" type="box" size="0.22578914077136203 0.34968785150582316 0.021091788442638038" quat="0.9982720929771576 -0.0254241992027927 -0.008505968474274149 -0.05228849757084933" rgba="0.43427085525121123 0.27450422733281477 0.291224917415974 0.95" /><geom pos="1.9542218575402357 -1.428840523374435 -0.025" type="box" size="0.21476538795968003 0.2927751424272009 0.02075344455952577" quat="0.9946245750424502 -0.03456345286759793 -0.02282244781076996 -0.09490236205395312" rgba="0.6616966867820152 0.06121849035979773 0.2770848228581871 0.95" /><geom pos="1.9542218575402357 -1.0959940696642203 -0.025" type="box" size="0.24666476285542974 0.32146258217768675 0.022009967029367635" quat="0.9901022184076103 -0.012125201363215248 0.03175803481900178 -0.13616902665681846" rgba="0.9351218580530395 0.03271305843497921 0.0321650835119813 0.95" /><geom pos="1.9542218575402357 -0.8169458626739052 -0.025" type="box" size="0.3455186807159221 0.3245317491638923 0.027820711931893085" quat="0.9907418504126128 -0.00012741289363496066 0.031088045946012065 0.1321518180208102" rgba="0.9850118525036378 0.01259555581285087 0.0023925916835113668 0.95" /><geom pos="1.9542218575402357 -0.5120720243763288 -0.025" type="box" size="0.28849654797057644 0.33730794593543134 0.023896645690397907" quat="0.9918150154122927 0.022478369476471558 -0.01874214378453365 0.1242836680934092" rgba="0.5945770533805618 0.2744641302726535 0.13095881634678475 0.95" /><geom pos="1.9542218575402357 -0.24487118130002639 -0.025" type="box" size="0.17423698249910607 0.29574513175948125 0.022530804543195244" quat="0.9969250729192358 0.028916720582521677 -0.02413483609628915 0.06871485969085808" rgba="0.801805815084095 0.07448335517051373 0.12371082974539128 0.95" /><geom pos="1.9542218575402357 0.10142786804489168 -0.025" type="box" size="0.1555681351547054 0.3340325748695337 0.023011254564026182" quat="0.996426968837984 -0.0093648131358123 -0.03457610362843925 0.07648587520028735" rgba="0.8162271496521025 0.003230923582795418 0.18054192676510206 0.95" /><geom pos="1.9542218575402357 0.43114715806778126 -0.025" type="box" size="0.16315076155455108 0.29288920741713076 0.02796940723894114" quat="0.994804662697516 -0.005140048529004247 -0.0043311072549661895 -0.10158003980284085" rgba="0.16812726853509719 0.5149466021400929 0.3169261293248099 0.95" /><geom pos="1.9542218575402357 0.7320666308233372 -0.025" type="box" size="0.27309513282539355 0.1552033538344186 0.02498726304445492" quat="0.9992801552592003 -0.018346187365230724 -0.028862302251076166 -0.016418167470082116" rgba="0.7587625654327596 0.13961055907548012 0.10162687549176033 0.95" /><geom pos="1.9542218575402357 1.0462908333916587 -0.025" type="box" size="0.21765771864169664 0.34862242346254707 0.02643515343098245" quat="0.994948604957069 -0.012170005842838528 -0.028854163964678867 0.09537610640861166" rgba="0.563489003170647 0.2108811949916648 0.22562980183768822 0.95" /><geom pos="1.9542218575402357 1.3958885391735718 -0.025" type="box" size="0.19157780408597713 0.16521924316963085 0.026166522545619665" quat="0.994506380846826 0.03612915022144539 0.019168148917082847 -0.09635520238324849" rgba="0.9863284030108018 0.00747113255184772 0.0062004644373504555 0.95" /><geom pos="1.9542218575402357 1.6894205986731619 -0.025" type="box" size="0.27101433486287 0.29314638529651865 0.020450157404432748" quat="0.9981231431008156 -0.03396631236475499 0.011301710281083127 -0.04968653917924691" rgba="0.8558616870866009 0.12181262105275255 0.02232569186064652 0.95" /><geom pos="1.9542218575402357 2.031043936998655 -0.025" type="box" size="0.3329447643413447 0.18241942127573652 0.027303494292596087" quat="0.9991029013987701 -0.024014228816292064 0.028940565936230612 -0.019471848248407173" rgba="0.7780278513440553 0.04259208916715126 0.17938005948879346 0.95" /><geom pos="1.9542218575402357 2.3537960154521658 -0.025" type="box" size="0.270627673919722 0.3440599070706462 0.02178950123653136" quat="0.9984814739382016 -0.021673528495754102 0.003977148805774926 -0.05048947070545439" rgba="0.4778357886765532 0.2776636508014383 0.24450056052200853 0.95" /><geom pos="1.9542218575402357 2.628090639104279 -0.025" type="box" size="0.30246762064095967 0.20847805215102147 0.02542185512020533" quat="0.9950060591085488 0.025850507938139193 -0.016609465466308863 -0.09496746407869858" rgba="0.0868168801786392 0.15466134198623105 0.7585217778351298 0.95" /><geom pos="1.9542218575402357 2.893710618797096 -0.025" type="box" size="0.2335357545488617 0.3483611808149064 0.0223809253946899" quat="0.9985275035449072 0.0005821639849416004 -0.004409302654802121 0.054065181027798295" rgba="0.6473639944246947 0.13820027232053908 0.2144357332547662 0.95" /><geom pos="1.9542218575402357 3.208712531023168 -0.025" type="box" size="0.30835407127484743 0.19664029792108562 0.021541469665418863" quat="0.9998455974621315 0.015652170263837886 0.007969667483502866 0.0005245968238091601" rgba="0.4616956492731492 0.07144674687320662 0.46685760385364417 0.95" /><geom pos="2.298360127720777 -2.7455959466064432 -0.025" type="box" size="0.20199388495288434 0.23490492492528275 0.028296578773230427" quat="0.997807874903865 0.018887333448115832 -0.004006331713055655 0.06329820472380847" rgba="0.4629921231305357 0.3867645715455509 0.1502433053239134 0.95" /><geom pos="2.298360127720777 -2.417093146953503 -0.025" type="box" size="0.3026483066926984 0.2515870357823143 0.027434427673036978" quat="0.997485842912217 0.02447263449450615 0.033106239413837626 0.05768067494816569" rgba="0.5730049877967632 0.2609208864743959 0.1660741257288409 0.95" /><geom pos="2.298360127720777 -2.074850213609113 -0.025" type="box" size="0.3440374433730148 0.23118608067428909 0.02558648214939923" quat="0.9987595137015879 0.03268439134337662 -0.0321439367753083 0.019440465057849236" rgba="0.23287834855499456 0.5384067545883068 0.22871489685669866 0.95" /><geom pos="2.298360127720777 -1.734407865667303 -0.025" type="box" size="0.16769902713928292 0.230937399712611 0.022316883854208217" quat="0.988955092941098 0.03065782188085785 0.01973349583462528 0.1436610985811067" rgba="0.7180087389685151 0.1377759362451349 0.14421532478634996 0.95" /><geom pos="2.298360127720777 -1.3964652908703055 -0.025" type="box" size="0.15223951894841486 0.19871300112022638 0.0241619454284349" quat="0.9903392051738368 0.024392099151999636 0.03802871257482779 0.13109958510427666" rgba="0.8938684665362759 0.06263345578962723 0.04349807767409683 0.95" /><geom pos="2.298360127720777 -1.1145579187119532 -0.025" type="box" size="0.24292459881732678 0.2974901458566957 0.023411933697071306" quat="0.9928337855404534 -0.013124726163348793 0.029147751386182943 -0.11514870577509359" rgba="0.9749588339142187 0.024683101551127705 0.00035806453465362514 0.95" /><geom pos="2.298360127720777 -0.8075879650149811 -0.025" type="box" size="0.16154716356348758 0.32287413659182673 0.02753992687827724" quat="0.9990675463598748 0.019835791182826277 0.011368681922880302 0.03662420333532398" rgba="0.8193049987793143 0.0655038279169346 0.11519117330375112 0.95" /><geom pos="2.298360127720777 -0.5384570330878105 -0.025" type="box" size="0.23150961856162272 0.25565847625944627 0.026020566944537714" quat="0.9916112772078621 -0.03003998696192575 -0.015942501421716618 -0.12470168702122035" rgba="0.4803414727782679 0.20545451466406978 0.31420401255766234 0.95" /><geom pos="2.298360127720777 -0.25952440415625055 -0.025" type="box" size="0.26518701154064683 0.2912675516358822 0.024201315247215062" quat="0.9956261960929069 -0.03652747600837176 -0.030102169070135187 -0.08054862237989735" rgba="0.1026963908850963 0.8139300440261462 0.08337356508875748 0.95" /><geom pos="2.298360127720777 0.08574873998393029 -0.025" type="box" size="0.33380360147101984 0.346981050860432 0.02308769318142377" quat="0.9940769095893927 -0.010219082662820829 0.009278281761109222 -0.10779880174795257" rgba="0.5122782359385826 0.4771210267722277 0.010600737289189754 0.95" /><geom pos="2.298360127720777 0.4299657426314645 -0.025" type="box" size="0.21768941476889414 0.1604505394148413 0.0244785890985888" quat="0.9992998737198888 0.01151263848474804 0.0293975040210835 0.020075066522036562" rgba="0.8983636340346419 0.10063903106444805 0.0009973349009100296 0.95" /><geom pos="2.298360127720777 0.71268540199073 -0.025" type="box" size="0.19705203596602158 0.18247059189620307 0.020269857030505406" quat="0.9958952219018478 -0.025952016244959804 -0.0023103698402169442 0.08668253594059247" rgba="0.9324998758929566 0.021169065717864387 0.04633105838917904 0.95" /><geom pos="2.298360127720777 1.0107269566506272 -0.025" type="box" size="0.2472861142965198 0.2022271181180983 0.021364162880372514" quat="0.9990594414901015 0.0015954010038277337 -0.021519463272325956 0.03761116543786212" rgba="0.2877505890921994 0.0985405983490892 0.6137088125587113 0.95" /><geom pos="2.298360127720777 1.3064201756740044 -0.025" type="box" size="0.2932867427415306 0.25699560274386113 0.028718427416312434" quat="0.9992203274618544 0.03461837325652711 -0.0033922204073647514 0.018676141485969307" rgba="0.792638291903372 0.1730058949859396 0.034355813110688416 0.95" /><geom pos="2.298360127720777 1.6272869753915087 -0.025" type="box" size="0.20140538078979542 0.29285273660507033 0.023145031402147808" quat="0.9932500726125767 0.018485556022980035 0.0266298545188767 -0.11137067981266771" rgba="0.45907809085925966 0.4761264008319708 0.06479550830876957 0.95" /><geom pos="2.298360127720777 1.8952644698626457 -0.025" type="box" size="0.34055524699304235 0.29162726645571596 0.02524359402600108" quat="0.9949108402945603 0.021692646137075677 -0.02452780285237644 0.0952902715662957" rgba="0.9782855435256567 0.010204610323772968 0.011509846150570368 0.95" /><geom pos="2.298360127720777 2.1541189616501013 -0.025" type="box" size="0.3090315477170516 0.2662133928600501 0.020779567802775137" quat="0.9998697296616701 0.011264764655253239 0.008687153855097107 -0.007626410784797368" rgba="0.8475820699839759 0.08818183082186185 0.06423609919416226 0.95" /><geom pos="2.298360127720777 2.448499776563957 -0.025" type="box" size="0.25779967974866136 0.318227907970489 0.02615562237724683" quat="0.9989078198478162 -0.019016218690393664 0.01821776831997666 0.03859616290567945" rgba="0.8607257104592667 0.07282921264001276 0.06644507690072053 0.95" /><geom pos="2.298360127720777 2.7280694260692577 -0.025" type="box" size="0.3319273799190111 0.31628435843752817 0.02346925071529289" quat="0.9945301304213847 0.03149756784869939 -0.015050857096652248 -0.0984438652445965" rgba="0.8256427524985548 0.004579074890629149 0.16977817261081607 0.95" /><geom pos="2.298360127720777 3.0612798454715646 -0.025" type="box" size="0.17080852170163663 0.20843423568123007 0.026681485850160766" quat="0.9942818495218605 0.023389227783745734 -0.022632171152141042 -0.1017070920044846" rgba="0.646845089740407 0.2242168973018398 0.1289380129577532 0.95" /><geom pos="2.6368924916007197 -2.6606235769025988 -0.025" type="box" size="0.1726016827980293 0.31348381489135296 0.021249531746475654" quat="0.9976163971014608 0.0005643109309911847 0.008732903619219417 -0.06844663747658575" rgba="0.13589652748756942 0.821776797898164 0.042326674614266535 0.95" /><geom pos="2.6368924916007197 -2.386709752201069 -0.025" type="box" size="0.29434749552681516 0.16501415496410482 0.02417969366589049" quat="0.9951205499132589 0.013718665621690888 -0.028017821110856312 -0.09360497344742694" rgba="0.5083048184679486 0.37880469860305743 0.11289048292899395 0.95" /><geom pos="2.6368924916007197 -2.084115734212584 -0.025" type="box" size="0.15812175690065872 0.23676319961256015 0.029288001612504545" quat="0.998412299160613 0.020384333796182656 0.002079037293605341 0.05246939512169121" rgba="0.4125294442568047 0.4407546218716137 0.1467159338715816 0.95" /><geom pos="2.6368924916007197 -1.7573316817011777 -0.025" type="box" size="0.3244352000517517 0.18793132591811385 0.027121349370057737" quat="0.998946410943398 -0.03167547983364143 0.03318771333772848 0.0011435576178722687" rgba="0.29810382099120813 0.48541162861099824 0.21648455039779363 0.95" /><geom pos="2.6368924916007197 -1.4282857842873558 -0.025" type="box" size="0.3030380279305719 0.27677511101227653 0.02547539544855372" quat="0.9898172250809721 -0.023244713665287242 0.00010977987543728555 0.140433372700373" rgba="0.7336539088724198 0.16577879935815068 0.10056729176942955 0.95" /><geom pos="2.6368924916007197 -1.1167934726387223 -0.025" type="box" size="0.293790726730226 0.3491527200881942 0.024257241499491395" quat="0.9962042304859939 0.010769672567765745 -0.003850654926007719 -0.08629204929327172" rgba="0.8144579473723987 0.1706638445347799 0.014878208092821366 0.95" /><geom pos="2.6368924916007197 -0.8129881770135685 -0.025" type="box" size="0.32295209513019557 0.18275776086077056 0.02337963947281433" quat="0.9985934053782476 0.008181748102810903 -0.02449625764598271 0.04630554064470847" rgba="0.804691830515397 0.14767000750045764 0.047638161984145305 0.95" /><geom pos="2.6368924916007197 -0.4662080960444386 -0.025" type="box" size="0.2864655229713832 0.22862597999518283 0.022474946417248162" quat="0.9973574520747848 -0.020211884198337953 0.033368941420093993 0.0612870808290691" rgba="0.6540719939389095 0.22399285047001535 0.12193515559107518 0.95" /><geom pos="2.6368924916007197 -0.20147489205980307 -0.025" type="box" size="0.2375313581318532 0.21149507681777724 0.0260927211750503" quat="0.9987085580784737 0.019846981308720094 0.031759899996682474 -0.034331066192995086" rgba="0.13192921557339632 0.7296693848331957 0.13840139959340803 0.95" /><geom pos="2.6368924916007197 0.12481268520439315 -0.025" type="box" size="0.2506580200183958 0.2213636272676041 0.027150199370482214" quat="0.9921669114914633 0.0170072269427841 0.021215351274873947 -0.12192408639596786" rgba="0.32381366506627096 0.05215761059384498 0.6240287243398841 0.95" /><geom pos="2.6368924916007197 0.43657883741965 -0.025" type="box" size="0.33274572305598416 0.27387112939457203 0.0207340141178428" quat="0.9950538559014568 0.005794612271578097 -0.015452991058568242 -0.09795637494113651" rgba="0.9432077481509565 0.04683995552317996 0.009952296325863502 0.95" /><geom pos="2.6368924916007197 0.688108857356466 -0.025" type="box" size="0.18793497063451117 0.20929470598613556 0.028630278533791523" quat="0.9997022214646055 0.016473909344937688 0.004790292490370016 0.017353149785688374" rgba="0.059477001106431615 0.4215509355272149 0.5189720633663535 0.95" /><geom pos="2.6368924916007197 1.0096708057910675 -0.025" type="box" size="0.31924703344837707 0.15054102418448612 0.0246207340872947" quat="0.991753083747405 -0.006466671559426923 -0.009003306688366016 -0.1276829804834234" rgba="0.9354851310796587 0.05116349216631436 0.013351376754026943 0.95" /><geom pos="2.6368924916007197 1.2851550124522406 -0.025" type="box" size="0.3396184644239678 0.24737887323880534 0.026099763148004683" quat="0.993336316025029 0.018017100897622568 0.01965218796559913 -0.11212554949356321" rgba="0.8510695330415711 0.005454127008474704 0.14347633994995423 0.95" /><geom pos="2.6368924916007197 1.571808550935839 -0.025" type="box" size="0.30117102566965404 0.16461562911203836 0.029369189745931237" quat="0.990222151522118 -0.036456805769821535 -0.023423842829755844 -0.13259832402808033" rgba="0.9408660972878234 0.010060218499336793 0.049073684212839766 0.95" /><geom pos="2.6368924916007197 1.8546569492772873 -0.025" type="box" size="0.329381978054115 0.2057766376583158 0.029906415812648163" quat="0.9970450787439927 0.006056256605000152 0.004137545571276938 -0.07646772799662217" rgba="0.8637839370292002 0.07446414605300718 0.061751916917792624 0.95" /><geom pos="2.6368924916007197 2.1958594542988754 -0.025" type="box" size="0.3021595666968637 0.19788895684005436 0.02338569667412198" quat="0.9946066805618603 0.01484426214429753 0.012954306188145519 -0.10183017634421027" rgba="0.3942774894016102 0.1408326536314774 0.4648898569669124 0.95" /><geom pos="2.6368924916007197 2.515102794253959 -0.025" type="box" size="0.1959736283743014 0.3367598430713101 0.0210097677902221" quat="0.9890599121907532 0.02882941708428764 -0.003912446257042419 0.14461689933090646" rgba="0.28578905830105206 0.42412732272790454 0.2900836189710434 0.95" /><geom pos="2.6368924916007197 2.8287621122295032 -0.025" type="box" size="0.29612321513886314 0.1677934625979603 0.02057058094735541" quat="0.9982991603334991 -0.01824119071161709 -0.030247946938383063 0.04638002959104216" rgba="0.801966740158069 0.0390809768583949 0.1589522829835361 0.95" /><geom pos="2.6368924916007197 3.082088817257235 -0.025" type="box" size="0.2590909461772717 0.3316861194637001 0.029195396575118014" quat="0.9984323789240996 -0.02843535244778941 -0.0044108418967034975 -0.048007915190052895" rgba="0.7246575183376529 0.10574454539159665 0.16959793627075043 0.95" /><geom pos="2.89456235812464 -2.7340021715789664 -0.025" type="box" size="0.341272256649502 0.2785296704103094 0.020018111200502026" quat="0.9991171695459726 0.02047779365412687 -0.015033645439818003 -0.03345939315488508" rgba="0.2748809197406965 0.30393495700208734 0.42118412325721616 0.95" /><geom pos="2.89456235812464 -2.3876701899150037 -0.025" type="box" size="0.345249351531775 0.33568464198255193 0.02002222807595943" quat="0.9901257384181866 0.004216032610742693 -0.0024773863049967313 -0.14009678707222942" rgba="0.688623148270701 0.30805750520723874 0.003319346522060229 0.95" /><geom pos="2.89456235812464 -2.11320002461844 -0.025" type="box" size="0.3425823262624333 0.2314215482303637 0.02704923529181846" quat="0.998285642681232 0.02703341620077998 -0.004025808975259912 -0.051756766583023486" rgba="0.09777677893398862 0.26669756048950555 0.6355256605765058 0.95" /><geom pos="2.89456235812464 -1.860639351729708 -0.025" type="box" size="0.3125470504474132 0.2543208088503454 0.027504278609065985" quat="0.9977802269623416 0.0003619682472369662 -0.00840500147678819 -0.06605939457898104" rgba="0.6669391674715189 0.19066400835189132 0.14239682417658975 0.95" /><geom pos="2.89456235812464 -1.6043837486788033 -0.025" type="box" size="0.2195134236326936 0.323272556787851 0.02309895120279534" quat="0.9945617441465586 -0.007710036213285906 0.02187642246147787 -0.10153282504703429" rgba="0.8999065334730897 0.07694837125832182 0.02314509526858849 0.95" /><geom pos="2.89456235812464 -1.3513128855906382 -0.025" type="box" size="0.1803137309741284 0.2553002322144371 0.02281857422336349" quat="0.9979037898849814 -0.01095800275275998 0.007166057638672831 -0.0633766197172143" rgba="0.9533364879919035 0.01274206069934463 0.033921451308751856 0.95" /><geom pos="2.89456235812464 -1.0112959664860965 -0.025" type="box" size="0.16159876563438647 0.22288558160150965 0.02511361808440734" quat="0.9932200846319983 0.0008789326570912707 -0.0023992213409529386 -0.1162210596146314" rgba="0.413581568391194 0.48074865048320514 0.10566978112560088 0.95" /><geom pos="2.89456235812464 -0.7608006062464527 -0.025" type="box" size="0.17428245431430253 0.32635509158913156 0.028618671868828858" quat="0.9913714571076986 0.020847196856214136 0.03418830945738906 0.12481661713026142" rgba="0.15458309532022552 0.641795444912056 0.2036214597677185 0.95" /><geom pos="2.89456235812464 -0.5091781351405582 -0.025" type="box" size="0.15934023637344236 0.161689441338565 0.024786241569039403" quat="0.996642422553961 0.015284384345224843 0.032273715419843384 0.07367955248207175" rgba="0.16542258159912948 0.8071161743811096 0.02746124401976091 0.95" /><geom pos="2.89456235812464 -0.23468338021826618 -0.025" type="box" size="0.2436223130879097 0.1563388498971224 0.027283559578658807" quat="0.9950797507624891 0.02126761194291701 -0.02216542094780396 0.09419486407928461" rgba="0.5702740045812741 0.2503365344758698 0.17938946094285613 0.95" /><geom pos="2.89456235812464 0.09197524344665409 -0.025" type="box" size="0.3003414041800737 0.2984355751602462 0.028932142610371085" quat="0.997691310072278 0.015681595853712694 -0.03337493504315033 -0.05702851101517674" rgba="0.590721847219561 0.07713125799918132 0.3321468947812577 0.95" /><geom pos="2.89456235812464 0.4028842003148325 -0.025" type="box" size="0.20534439230676121 0.3108429529897745 0.02282209111681912" quat="0.9995973741368176 -0.025389018483561093 -0.009955807103050808 0.007833853722623987" rgba="0.5309344245125891 9.164071020270305e-05 0.4689739347772082 0.95" /><geom pos="2.89456235812464 0.6704432056670178 -0.025" type="box" size="0.2686034102223405 0.3139423786078206 0.028478717638610856" quat="0.9895831714701504 0.02365582118005276 -0.024276514555923924 -0.13991497313866041" rgba="0.4222042651269239 0.19931793630377626 0.37847779856929986 0.95" /><geom pos="2.89456235812464 0.9241996111344268 -0.025" type="box" size="0.1967205402587082 0.1535040476525404 0.027822513181727633" quat="0.9975094931888125 -0.004373274925490511 -0.008799374406555883 0.06984451642525254" rgba="0.9983378263138116 0.0004841654784664482 0.0011780082077219247 0.95" /><geom pos="2.89456235812464 1.1955663560476717 -0.025" type="box" size="0.1892403542822726 0.15415358716979027 0.02399548649770982" quat="0.9963298690925104 -0.028791937984847374 0.01852930127993852 -0.0784505019439329" rgba="0.08093155212744219 0.22856770385221423 0.6905007440203436 0.95" /><geom pos="2.89456235812464 1.4597027744287558 -0.025" type="box" size="0.24738401852069675 0.3145677905493247 0.02645374326856879" quat="0.9997517208961842 0.01763073627327514 -0.0077154223840036115 0.011230581508396847" rgba="0.21012853157512834 0.0810394189593056 0.7088320494655661 0.95" /><geom pos="2.89456235812464 1.768173093909831 -0.025" type="box" size="0.2042660774999167 0.28018481894214753 0.021430439029082655" quat="0.9982373486212879 0.007387570327534057 -0.019077667607996722 0.05571052163492704" rgba="0.49426084968391504 0.26143240132652107 0.2443067489895639 0.95" /><geom pos="2.89456235812464 2.0866262723002906 -0.025" type="box" size="0.33950931559657266 0.21359698419743117 0.02298266250292904" quat="0.9982103828049872 0.01207543909544073 0.0337447936940051 -0.04786965980161407" rgba="0.27236958108176834 0.22121601849356284 0.5064144004246688 0.95" /><geom pos="2.89456235812464 2.3665473152551586 -0.025" type="box" size="0.20242876250756095 0.2273870602316089 0.02412183543137501" quat="0.9896743418002689 -0.02067826743636648 -0.014478857304281936 -0.14109383093954553" rgba="0.9366374592542777 0.04709622507282484 0.016266315672897498 0.95" /><geom pos="2.89456235812464 2.647868256628577 -0.025" type="box" size="0.1876286293997704 0.31785814705776566 0.02159915261084319" quat="0.992478154413278 -0.0006595835270495816 -0.0002908766470957655 0.12241974249589149" rgba="0.7183503457572677 0.08935450378727088 0.19229515045546136 0.95" /><geom pos="3.2266647198125407 -2.683108625295831 -0.025" type="box" size="0.3353555792085575 0.33730603214919336 0.02441331223836574" quat="0.9986172579354579 -0.020257411644574234 0.029713140329666207 0.03834499600572205" rgba="0.720426891614417 0.2630322685298576 0.01654083985572541 0.95" /><geom pos="3.2266647198125407 -2.3799244117145215 -0.025" type="box" size="0.2737129085950655 0.30983946356321707 0.02532438160386067" quat="0.9986884667392061 -0.028221013590457134 -0.0027491733346696476 -0.042630538818986985" rgba="0.44267526380290545 0.2816973435374471 0.2756273926596475 0.95" /><geom pos="3.2266647198125407 -2.058758197860436 -0.025" type="box" size="0.1996925247590457 0.17871560012241455 0.029142092380962464" quat="0.9919344353639226 0.03415971303404161 -0.025809510462119368 0.1193023851999369" rgba="0.6306666539578487 0.2368733615736103 0.132459984468541 0.95" /><geom pos="3.2266647198125407 -1.7176616287299458 -0.025" type="box" size="0.21059729370157745 0.34504604011799267 0.029924244164386334" quat="0.9991354164495405 -0.0031044946252035475 -0.02519999285842441 0.032920237989126425" rgba="0.8005460792293257 0.018092658602438885 0.18136126216823537 0.95" /><geom pos="3.2266647198125407 -1.454798764316924 -0.025" type="box" size="0.1900464752848202 0.3308907550599771 0.028411861827760405" quat="0.9969206228157059 0.0012110074152618898 0.005440249337253096 -0.07821898077150957" rgba="0.5840896980358107 0.062397915743930554 0.35351238622025877 0.95" /><geom pos="3.2266647198125407 -1.1449288164723133 -0.025" type="box" size="0.18954756260670444 0.34343352667581223 0.028021566167685415" quat="0.9921732891080106 0.018148848959254425 0.0337839859015415 0.11883360618381665" rgba="0.763953469014711 0.1973823383971846 0.03866419258810444 0.95" /><geom pos="3.2266647198125407 -0.8521535635160356 -0.025" type="box" size="0.29350081177822424 0.2623088009262472 0.020517131315751995" quat="0.9935784521099564 -0.02125748370187518 -0.008998156551108367 -0.11076557257618085" rgba="0.8480002557976096 0.04399270552491598 0.1080070386774744 0.95" /><geom pos="3.2266647198125407 -0.5391780888042241 -0.025" type="box" size="0.15039079679276188 0.18814862760986054 0.025302103817549864" quat="0.9997933673289942 -0.006010352128051552 0.010392162168266394 0.01640430668197664" rgba="0.294318245556641 0.6070482807724908 0.09863347367086817 0.95" /><geom pos="3.2266647198125407 -0.26654747866805595 -0.025" type="box" size="0.26144116908803294 0.16901590819566575 0.020072437022016373" quat="0.9987314166321767 -0.031919798243413365 -0.029634512861734807 -0.025268153067308632" rgba="0.9657128073361169 0.034228825509185275 5.83671546978623e-05 0.95" /><geom pos="3.2266647198125407 -0.004859737307821632 -0.025" type="box" size="0.24188253516766406 0.29327761090561005 0.023848674289068766" quat="0.9982996935300077 0.014075274936783363 0.020971611249110726 0.05253379916742134" rgba="0.2778265969548712 0.27250716244789225 0.44966624059723653 0.95" /><geom pos="3.2266647198125407 0.30159782834769233 -0.025" type="box" size="0.274486536555826 0.25183517767724256 0.02117158622924545" quat="0.997113469626848 0.029768182404220023 -0.011680037402749028 -0.06886334824366622" rgba="0.8982633599143348 0.022514649010915138 0.07922199107475004 0.95" /><geom pos="3.2266647198125407 0.5667752419100589 -0.025" type="box" size="0.1543001824658706 0.3161030885686583 0.02081828885299662" quat="0.9900718441439643 0.0007977793068949723 0.02499649158046861 0.13831949389082682" rgba="0.4199462566212634 0.38172929628102437 0.19832444709771224 0.95" /><geom pos="3.2266647198125407 0.8523451198799665 -0.025" type="box" size="0.1969536949983916 0.2643528069134757 0.020116099640580865" quat="0.9927502558732857 -0.018049998239468984 -0.03397977936115246 0.11387054764796907" rgba="0.91927437280941 0.044944245926009596 0.03578138126458036 0.95" /><geom pos="3.2266647198125407 1.1777080610666903 -0.025" type="box" size="0.29976449194221966 0.28474101177987576 0.029125952546687442" quat="0.9986359327593141 -0.0020896615303390145 -0.009627060756752839 0.051275986756076" rgba="0.31539330317979597 0.5090826807430321 0.17552401607717194 0.95" /><geom pos="3.2266647198125407 1.4909659807670685 -0.025" type="box" size="0.25096879875969563 0.23713423463532074 0.024980031316516462" quat="0.9967276852307353 -0.016946347937987383 0.012417685052934294 -0.07805474927300123" rgba="0.14572698680929586 0.3745152284641791 0.479757784726525 0.95" /><geom pos="3.2266647198125407 1.753662008250969 -0.025" type="box" size="0.31363227166973173 0.1630387755831802 0.025740422654953538" quat="0.9990203959390428 -0.0035409333851137204 0.032559618882358095 0.02975872152489443" rgba="0.38606584634649455 0.08136777633069628 0.5325663773228092 0.95" /><geom pos="3.2266647198125407 2.0988301753141183 -0.025" type="box" size="0.31102671919049685 0.22175128634997054 0.022046535996524192" quat="0.9950767716103486 -0.008440090578944657 -0.032643483384462706 0.09319542083747256" rgba="0.6057349007379431 0.30969278117206134 0.08457231808999555 0.95" /><geom pos="3.2266647198125407 2.363796814168172 -0.025" type="box" size="0.29638928054215286 0.32194042983222304 0.02160500241466603" quat="0.989147787714006 0.0025836392176679995 -0.009969856105558639 -0.1465625492344987" rgba="0.09470423474028222 0.2298298883482101 0.6754658769115076 0.95" /><geom pos="3.2266647198125407 2.616010642667872 -0.025" type="box" size="0.23265315245989182 0.34043652974641647 0.021587776883830793" quat="0.9917611896660856 0.013049671127391886 -0.024898784224331866 0.12497799526207631" rgba="0.425405399299688 0.40495507134075126 0.16963952935956073 0.95" /><geom pos="3.2266647198125407 2.881469282900489 -0.025" type="box" size="0.3498203440322751 0.3207013267837606 0.023617794386422194" quat="0.9923686344524332 0.011457856350836907 0.01596946205872265 -0.12172997644134921" rgba="0.21424523028448894 0.1870465900087809 0.5987081797067302 0.95" /></worldbody>

  <contact>
    

    
    

    
    
  </contact>

  <actuator>
    <motor name="Lleg_hip_p_joint" joint="Lleg_hip_p_joint" gear="1" ctrllimited="true" ctrlrange="-200 200" />
    <motor name="Lleg_hip_r_joint" joint="Lleg_hip_r_joint" gear="1" ctrllimited="true" ctrlrange="-200 200" />
    <motor name="Lleg_hip_y_joint" joint="Lleg_hip_y_joint" gear="1" ctrllimited="true" ctrlrange="-200 200" />
    <motor name="Lleg_knee_joint" joint="Lleg_knee_joint" gear="1" ctrllimited="true" ctrlrange="-200 200" />
    <motor name="Lleg_ankle_p_joint" joint="Lleg_ankle_p_joint" gear="1" ctrllimited="true" ctrlrange="-200 200" />
    <motor name="Lleg_ankle_r_joint" joint="Lleg_ankle_r_joint" gear="1" ctrllimited="true" ctrlrange="-200 200" />

    <motor name="Rleg_hip_p_joint" joint="Rleg_hip_p_joint" gear="1" ctrllimited="true" ctrlrange="-200 200" />
    <motor name="Rleg_hip_r_joint" joint="Rleg_hip_r_joint" gear="1" ctrllimited="true" ctrlrange="-200 200" />
    <motor name="Rleg_hip_y_joint" joint="Rleg_hip_y_joint" gear="1" ctrllimited="true" ctrlrange="-200 200" />
    <motor name="Rleg_knee_joint" joint="Rleg_knee_joint" gear="1" ctrllimited="true" ctrlrange="-200 200" />
    <motor name="Rleg_ankle_p_joint" joint="Rleg_ankle_p_joint" gear="1" ctrllimited="true" ctrlrange="-200 200" />
    <motor name="Rleg_ankle_r_joint" joint="Rleg_ankle_r_joint" gear="1" ctrllimited="true" ctrlrange="-200 200" />

    <motor name="Larm_shoulder_p_joint" joint="Larm_shoulder_p_joint" gear="1" ctrllimited="true" ctrlrange="-200 200" />
    <motor name="Rarm_shoulder_p_joint" joint="Rarm_shoulder_p_joint" gear="1" ctrllimited="true" ctrlrange="-200 200" />
  </actuator>

  <sensor>
    <accelerometer name="imu_acc" site="imu_site" />
    <gyro name="imu_gyro" site="imu_site" />
    <framepos name="imu_pos" objtype="site" objname="imu_site" />
    <framelinvel name="imu_linvel" objtype="site" objname="imu_site" />

    <framequat name="orientation" objtype="site" noise="0.001" objname="imu" />
    <framepos name="position" objtype="site" noise="0.001" objname="imu" />
    <gyro name="angular-velocity" site="imu" noise="0.005" cutoff="34.9" />
    <velocimeter name="linear-velocity" site="imu" noise="0.001" cutoff="30" />
    <accelerometer name="linear-acceleration" site="imu" noise="0.005" cutoff="157" />
    <magnetometer name="magnetometer" site="imu" />
  </sensor>
</mujoco>