<mujoco model="hhfc">
  <compiler angle="radian" meshdir="../meshes/" eulerseq="zyx" />
  <statistic meansize="0.201559" extent="2.948112" center="0.00499457 0 0.337764"/>

  <default>
      <joint limited='true'/>
      <motor ctrllimited='true'/>
      <geom  condim='4' contype="1" conaffinity="15" solref='0.001 2' friction='0.9 0.2 0.2'/>
      <equality solref='0.001 2'/>
      <default class='visualgeom'>
          <geom material='visualgeom' condim='1' contype='0' conaffinity='0'/>
      </default>
      <default class='visualgeom2'>
          <geom material='visualgeom2' condim='1' contype='0' conaffinity='0'/>
      </default>
      <default class='obstacle'>
          <geom material='obstacle' condim='3' contype='1' conaffinity='15'/>
      </default>
      <default class='leg_joint_param'>
          <!--<joint damping="0.01" frictionloss="0.01" armature="0.01"/>-->
          <joint damping="0.0" frictionloss="0.0" armature="0.0"/>
      </default>
  </default>

  <asset>
    <!-- Set ground -->
    <texture name="grid" type="2d" builtin="checker" width="512" height="512" rgb1=".1 .2 .3" rgb2=".2 .3 .4"/>
    <material name="grid" texture="grid" texrepeat="1 1" texuniform="true" reflectance=".2"/>
  </asset>

  <option timestep="0.001" integrator="RK4">
    <flag frictionloss="enable" />
  </option>

  <visual>
    <map stiffness="300" force="0.1" zfar="30"/>
    <rgba haze="0.15 0.25 0.35 1"/>
    <global offwidth="2560" offheight="1440" elevation="-30" azimuth="120"/>
  </visual>

  <asset>
    <mesh name="base_thorax" file="base_thorax.STL"/>
    <mesh name="Lleg_hip_p" file="Lleg_hip_p.STL"/>
    <mesh name="Lleg_hip_r" file="Lleg_hip_r.STL"/>
    <mesh name="Lleg_hip_y" file="Lleg_hip_y.STL"/>
    <mesh name="Lleg_knee" file="Lleg_knee.STL"/>
    <mesh name="Lleg_ankle_p" file="Lleg_ankle_p.STL"/>
    <mesh name="Lleg_ankle_r" file="Lleg_ankle_r.STL"/>
    <mesh name="Rleg_hip_p" file="Rleg_hip_p.STL"/>
    <mesh name="Rleg_hip_r" file="Rleg_hip_r.STL"/>
    <mesh name="Rleg_hip_y" file="Rleg_hip_y.STL"/>
    <mesh name="Rleg_knee" file="Rleg_knee.STL"/>
    <mesh name="Rleg_ankle_p" file="Rleg_ankle_p.STL"/>
    <mesh name="Rleg_ankle_r" file="Rleg_ankle_r.STL"/>
    <mesh name="Larm_shoulder_p" file="Larm_shoulder_p.STL"/>
    <mesh name="Rarm_shoulder_p" file="Rarm_shoulder_p.STL"/>
  </asset>

  <worldbody>
    <!-- Main Light Source -->
    <light name="main_light" diffuse="2 2 2" specular="0.5 0.5 0.5" pos="0 0 40" dir="0 0 -1" castshadow="true"/>
    <!-- Auxiliary Light Sources-->
    <light name="aux_light1" diffuse=".8 .8 .8" pos=" 10 0 1" dir="-1 0 0" castshadow="false"/>
    <light name="aux_light2" diffuse=".8 .8 .8" pos="-10 0 1" dir=" 1 0 0" castshadow="false"/>
    <light name="aux_light3" diffuse=".8 .8 .8" pos="0  10 1" dir="0 -1 0" castshadow="false"/>
    <light name="aux_light4" diffuse=".8 .8 .8" pos="0 -10 1" dir="0  1 0" castshadow="false"/>
    <!-- Floor -->
    <geom name="floor" type="plane" size="0 0 0.05" material="grid"/>

    <body name="base_thorax" pos="0 0 0.906" euler="0 0 0">
      <!-- <inertial pos="0.0071545 -0.00014864 0.10711"  mass="21.7513" fullinertia="0.096973 0.056865 0.10587 -2.6251E-05 0.00041701 2.8904E-05"/> -->
      <inertial pos="0.0063842 0.00017156 0.099276"  mass="21.7513" fullinertia="0.51774 0.41969 0.193013 3.96E-05 0.000772 0.000516"/>
      <freejoint name="base_thorax"/>
      <geom size="0.2 0.175 0.3" pos="0 0 0.2" type="box" rgba="0.89804 0.91765 0.92941 0"/>
      <geom type="mesh" contype="0" conaffinity="0" group="1" density="0" rgba="0.89804 0.91765 0.92941 1" mesh="base_thorax"/>
      <site name="imu_site" pos="0 0 0" size="0.02" rgba="1 0 0 1" type="sphere" />
      <site name='imu' size='0.01' pos='0.0 0 0.0'/>

      <body name="Lleg_hip_p" pos="0.0074413 0.070763 -0.096701" quat="1 -1.49195e-05 9.221e-11 -6.1805e-06">
        <!-- <inertial pos="-0.0065868 0.038281 -0.019058" quat="0.689291 0.159395 -0.159229 0.688562" mass="0.79889" diaginertia="0.00162063 0.0016035 0.00132837"/> -->
        <inertial pos="-0.0080076 0.037645 -0.018534" quat="0.414257 0.709337 0.188122 0.53837" mass="0.8" diaginertia="0.00249693 0.00187387 0.00185259"/>
        <joint name="Lleg_hip_p_joint" pos="0 0 0" axis="0 -1 0" range="-1.5708 3.1416" class="leg_joint_param"/>
        <geom type="mesh" contype="0" conaffinity="0" group="1" density="0" rgba="0.89804 0.91765 0.92941 1" mesh="Lleg_hip_p"/>

        <body name="Lleg_hip_r" pos="-0.048264 0.063739 -0.039998" quat="1 -1.49194e-05 -1.55901e-05 6.18077e-06">
          <!-- <inertial pos="0.041051 0.0017918 -0.012588" quat="0.794556 0.60374 -0.0545298 0.0347217" mass="2.2937" diaginertia="0.00245553 0.0018219 0.00168278"/> -->
          <inertial pos="0.042398 0.0021906 -0.014152" quat="0.717776 -0.00466495 -0.115772 0.686566" mass="2.4" diaginertia="0.00470642 0.00421976 0.00322592"/>
          <joint name="Lleg_hip_r_joint" pos="0 0 0" axis="1 0 0" range="-0.12217 0.52359" class="leg_joint_param"/>
          <geom type="mesh" contype="0" conaffinity="0" group="1" density="0" rgba="0.89804 0.91765 0.92941 1" mesh="Lleg_hip_r"/>
          <geom size="0.05 0.1" pos="0.05 0 -0.225" type="cylinder" rgba="0.89804 0.91765 0.92941 0"/>

          <body name="Lleg_hip_y" pos="0.048263 0.0075949 -0.073228" quat="1 -0.0006421 0 0">
            <!-- <inertial pos="0.0012764 -0.012311 -0.11618" quat="0.695183 -0.0722459 0.00468686 0.715178" mass="4.5531" diaginertia="0.00732582 0.00604015 0.00428763"/> -->
            <inertial pos="0.0012794 -0.012189 -0.11613" quat="0.996816 -0.0530944 -0.0162506 -0.0572273" mass="4.7" diaginertia="0.0299281 0.0291921 0.00657282"/>
            <joint name="Lleg_hip_y_joint" pos="0 0 0" axis="0 0 1" range="-1.0472 1.2217" class="leg_joint_param"/>
            <geom type="mesh" contype="0" conaffinity="0" group="1" density="0" rgba="0.75294 0.75294 0.75294 1" mesh="Lleg_hip_y"/>

            <body name="Lleg_knee" pos="0 0 -0.27926">
              <!-- <inertial pos="-0.0071953 0.00012337 -0.15866" quat="0.705841 -0.00283084 0.00774909 0.708322" mass="4.1746" diaginertia="0.0171054 0.0159176 0.00207267"/> -->
              <inertial pos="-0.0093168 0.0004254 -0.1569" quat="0.997868 -0.0245164 0.0336298 0.0502756" mass="4.4" diaginertia="0.033405 0.0314582 0.0069106"/>
              <joint name="Lleg_knee_joint" pos="0 0 0" axis="0 -1 0" range="-1.5708 0" class="leg_joint_param"/>
              <geom type="mesh" contype="0" conaffinity="0" group="1" density="0" rgba="0.89804 0.91765 0.92941 1" mesh="Lleg_knee"/>
              <geom size="0.05 0.125" pos="0 0 -0.175" type="cylinder" rgba="0.89804 0.91765 0.92941 0"/>

              <body name="Lleg_ankle_p" pos="0 0 -0.35">
                <!-- <inertial pos="0.0010341 -8.5615e-08 7.218e-08" quat="0.500022 0.499956 -0.500017 0.500004" mass="0.15381" diaginertia="4.3137e-05 2.9623e-05 2.6222e-05"/> -->
                <inertial pos="0.00066352 -5.5018e-08 8.196e-09" quat="0.499943 0.499943 -0.500057 0.500057" mass="0.24" diaginertia="0.000135 0.000113 5.24e-05"/>
                <joint name="Lleg_ankle_p_joint" pos="0 0 0" axis="0 1 0" range="-1.6108 0.6108" class="leg_joint_param"/>
                <geom type="mesh" contype="0" conaffinity="0" group="1" density="0" rgba="0.89804 0.91765 0.92941 1" mesh="Lleg_ankle_p"/>

                <body name="Lleg_ankle_r">
                  <!-- <inertial pos="0.021653 2.4677e-08 -0.044273" quat="-2.3025e-06 0.722358 2.2042e-06 0.691519" mass="0.87283" diaginertia="0.00399262 0.0029662 0.00124638"/> -->
                  <inertial pos="0.021653 2.4998e-08 -0.044273" quat="1.13655e-06 0.717415 -1.10364e-06 0.696646" mass="0.88" diaginertia="0.00668964 0.005724 0.00130736"/>
                  <joint name="Lleg_ankle_r_joint" pos="0 0 0" axis="1 0 0" range="-0.34453292519943295 0.34453292519943295" class="leg_joint_param"/>
                  <geom type="mesh" contype="0" conaffinity="0" group="1" density="0" rgba="0.89804 0.91765 0.92941 1" mesh="Lleg_ankle_r"/>
                  <geom name="Lleg_ankle_r" type="mesh" rgba="0.89804 0.91765 0.92941 0" mesh="Lleg_ankle_r"/>
                </body>
              </body>
            </body>
          </body>
        </body>
      </body>

      <body name="Rleg_hip_p" pos="0.0074402 -0.070762 -0.096701" quat="1 1.49195e-05 -9.221e-11 -6.1805e-06">
        <!-- <inertial pos="-0.0065825 -0.038282 -0.019058" quat="0.688727 -0.159254 0.159385 0.689122" mass="0.79889" diaginertia="0.00162064 0.0016035 0.00132836"/> -->
        <inertial pos="-0.0080033 -0.037645 -0.018534" quat="0.709009 0.414898 0.538551 0.187424" mass="0.8" diaginertia="0.00249686 0.00187362 0.00185253"/>
        <joint name="Rleg_hip_p_joint" pos="0 0 0" axis="0 -1 0" range="-1.5708 3.1416" class="leg_joint_param"/>
        <geom type="mesh" contype="0" conaffinity="0" group="1" density="0" rgba="0.89804 0.91765 0.92941 1" mesh="Rleg_hip_p"/>

        <body name="Rleg_hip_r" pos="-0.048261 -0.063738 -0.039998" quat="1 -1.49194e-05 -1.55901e-05 6.18077e-06">
          <!-- <inertial pos="0.040804 -0.0018825 -0.012645" quat="0.601911 0.796001 -0.0328958 0.0547996" mass="2.2802" diaginertia="0.00245492 0.00182183 0.00168105"/> -->
          <inertial pos="0.042392 -0.0022474 -0.014239" quat="0.688789 -0.114585 -0.00306577 0.715843" mass="2.4" diaginertia="0.00471825 0.00423405 0.00323269"/>
          <joint name="Rleg_hip_r_joint" pos="0 0 0" axis="1 0 0" range="-0.52359 0.12217" class="leg_joint_param"/>
          <geom type="mesh" contype="0" conaffinity="0" group="1" density="0" rgba="0.75294 0.75294 0.75294 1" mesh="Rleg_hip_r"/>
          <geom size="0.05 0.1" pos="0.05 0 -0.225" type="cylinder" rgba="0.75294 0.75294 0.75294 0"/>

          <body name="Rleg_hip_y" pos="0.048263 -0.0075949 -0.073228" quat="1 -0.0006421 1.559e-05 1.00103e-08">
            <!-- <inertial pos="0.0012764 0.012311 -0.11618" quat="0.715443 0.00472894 -0.072901 0.694841" mass="4.5154" diaginertia="0.00726745 0.00600923 0.00425672"/> -->
            <inertial pos="0.0012651 0.012199 -0.11598" quat="0.996226 0.0535852 -0.0154666 0.0665041" mass="4.7" diaginertia="0.0298237 0.0290669 0.00653037"/>
            <joint name="Rleg_hip_y_joint" pos="0 0 0" axis="0 0 1" range="-1.2217 1.0472" class="leg_joint_param"/>
            <geom type="mesh" contype="0" conaffinity="0" group="1" density="0" rgba="0.75294 0.75294 0.75294 1" mesh="Rleg_hip_y"/>

            <body name="Rleg_knee" pos="0 0 -0.27926">
              <!-- <inertial pos="-0.0071953 -0.00012337 -0.15866" quat="0.708482 0.00772113 -0.00291281 0.70568" mass="4.1724" diaginertia="0.0171044 0.0159176 0.00207196"/> -->
              <inertial pos="-0.0080323 -0.0016076 -0.15944" quat="0.503618 0.498429 -0.471667 0.524851" mass="4.4" diaginertia="0.0334195 0.0311732 0.00644732"/>
              <joint name="Rleg_knee_joint" pos="0 0 0" axis="0 -1 0" range="-1.5708 0" class="leg_joint_param"/>
              <geom type="mesh" contype="0" conaffinity="0" group="1" density="0" rgba="0.89804 0.91765 0.92941 1" mesh="Rleg_knee"/>
              <geom size="0.05 0.125" pos="0 0 -0.175" type="cylinder" rgba="0.89804 0.91765 0.92941 0"/>

              <body name="Rleg_ankle_p" pos="0 0 -0.35">
                <!-- <inertial pos="0.0010341 8.5615e-08 7.218e-08" quat="0.500017 0.500004 -0.500022 0.499956" mass="0.15381" diaginertia="4.3137e-05 2.9623e-05 2.6222e-05"/> -->
                <inertial pos="0.00099756 8.2521e-08 6.9572e-08" quat="0.5 0.5 -0.5 0.5" mass="0.24" diaginertia="0.000135 0.000113 5.3e-05"/>
                <joint name="Rleg_ankle_p_joint" pos="0 0 0" axis="0 1 0" range="-1.6108 0.6108" class="leg_joint_param"/>
                <geom type="mesh" contype="0" conaffinity="0" group="1" density="0" rgba="0.89804 0.91765 0.92941 1" mesh="Rleg_ankle_p"/>

                <body name="Rleg_ankle_r">
                  <!-- <inertial pos="0.021653 -2.4677e-08 -0.044273" quat="-2.30337e-06 0.722358 2.20503e-06 0.691519" mass="0.87283" diaginertia="0.00399262 0.0029662 0.00124638"/> -->
                  <inertial pos="0.021653 2.5592e-08 -0.044273" quat="0 0.717415 0 0.696646" mass="0.88" diaginertia="0.00668964 0.005725 0.00130736"/>
                  <joint name="Rleg_ankle_r_joint" pos="0 0 0" axis="1 0 0" range="-0.34453292519943295 0.34453292519943295" class="leg_joint_param"/>
                  <geom type="mesh" contype="0" conaffinity="0" group="1" density="0" rgba="0.89804 0.91765 0.92941 1" mesh="Rleg_ankle_r"/>
                  <geom name="Rleg_ankle_r" type="mesh" rgba="0.89804 0.91765 0.92941 0" mesh="Rleg_ankle_r"/>
                </body>
              </body>
            </body>
          </body>
        </body>
      </body>
      <body name="Larm_shoulder_p" pos="0.0074411 0.17676 0.2503" quat="1 -1.559e-05 0 0">
        <!-- <inertial pos="-4.1326e-06 0.029486 -0.15771" quat="0.705254 0.0509776 -0.0509816 0.705279" mass="0.8019" diaginertia="0.0017784 0.001659 0.000521319"/> -->
        <inertial pos="-4.0039e-06 0.029969 -0.17382" quat="0.706747 0.0225512 -0.0225512 0.706747" mass="0.9" diaginertia="0.0219046 0.021867 0.000591376"/>
        <joint name="Larm_shoulder_p_joint" pos="0 0 0" axis="0 -1 0" range="-3.1416 3.1416" class="leg_joint_param"/>
        <geom type="mesh" contype="0" conaffinity="0" group="1" density="0" rgba="0.89804 0.91765 0.92941 1" mesh="Larm_shoulder_p"/>
      </body>

      <body name="Rarm_shoulder_p" pos="0.0074404 -0.17676 0.2503" quat="1 1.55905e-05 0.0008107 -1.26392e-08">
        <!-- <inertial pos="0.00015217 -0.029574 -0.15842" quat="0.705279 -0.0512999 0.0506465 0.705255" mass="0.80628" diaginertia="0.0017788 0.0016592 0.000521562"/> -->
        <inertial pos="0.00016699 -0.03005 -0.17441" quat="0.706778 -0.0228932 0.0222331 0.706716" mass="0.9" diaginertia="0.0219559 0.021918 0.000591056"/>
        <joint name="Rarm_shoulder_p_joint" pos="0 0 0" axis="0 -1 0" range="-3.1416 3.1416" class="leg_joint_param"/>
        <geom type="mesh" contype="0" conaffinity="0" group="1" density="0" rgba="0.89804 0.91765 0.92941 1" mesh="Rarm_shoulder_p"/>
      </body>
    </body>

  </worldbody>

  <contact>
    <!-- <exclude body1="base_thorax" body2="Lleg_hip_p"/>
    <exclude body1="base_thorax" body2="Lleg_hip_r"/>
    <exclude body1="Lleg_hip_p"  body2="Lleg_hip_r"/>
    <exclude body1="Lleg_hip_r"  body2="Lleg_knee"/>

    <exclude body1="base_thorax" body2="Rleg_hip_p"/>
    <exclude body1="base_thorax" body2="Rleg_hip_r"/>
    <exclude body1="Rleg_hip_p"  body2="Rleg_hip_r"/>
    <exclude body1="Rleg_hip_r"  body2="Rleg_knee"/> -->

    <!--<pair name="left_feet" geom1="Lleg_ankle_r" geom2="floor" condim="6" friction="2 2 0.05 0.05 0.05"/>-->
    <!--<pair name="right_feet" geom1="Rleg_ankle_r" geom2="floor" condim="6" friction="2 2 0.05 0.05 0.05"/>-->

    <!--<pair name="left_feet" geom1="Lleg_ankle_r" geom2="floor" condim="6" friction="2 2 0.05 0.05 0.05"/>-->
    <!--<pair name="right_feet" geom1="Rleg_ankle_r" geom2="floor" condim="6" friction="2 2 0.05 0.05 0.05"/>-->
  </contact>

  <actuator>
    <motor name="Lleg_hip_p_joint"   joint="Lleg_hip_p_joint"   gear="1" ctrllimited="true" ctrlrange="-200 200"/>
    <motor name="Lleg_hip_r_joint"  joint="Lleg_hip_r_joint"  gear="1" ctrllimited="true" ctrlrange="-200 200"/>
    <motor name="Lleg_hip_y_joint"  joint="Lleg_hip_y_joint"  gear="1" ctrllimited="true" ctrlrange="-200 200"/>
    <motor name="Lleg_knee_joint"  joint="Lleg_knee_joint"  gear="1" ctrllimited="true" ctrlrange="-200 200"/>
    <motor name="Lleg_ankle_p_joint"   joint="Lleg_ankle_p_joint"   gear="1" ctrllimited="true" ctrlrange="-200 200"/>
    <motor name="Lleg_ankle_r_joint"  joint="Lleg_ankle_r_joint"  gear="1" ctrllimited="true" ctrlrange="-200 200"/>

    <motor name="Rleg_hip_p_joint"  joint="Rleg_hip_p_joint"  gear="1" ctrllimited="true" ctrlrange="-200 200"/>
    <motor name="Rleg_hip_r_joint"  joint="Rleg_hip_r_joint"  gear="1" ctrllimited="true" ctrlrange="-200 200"/>
    <motor name="Rleg_hip_y_joint"  joint="Rleg_hip_y_joint"  gear="1" ctrllimited="true" ctrlrange="-200 200"/>
    <motor name="Rleg_knee_joint"  joint="Rleg_knee_joint"  gear="1" ctrllimited="true" ctrlrange="-200 200"/>
    <motor name="Rleg_ankle_p_joint"   joint="Rleg_ankle_p_joint"   gear="1" ctrllimited="true" ctrlrange="-200 200"/>
    <motor name="Rleg_ankle_r_joint"  joint="Rleg_ankle_r_joint"  gear="1" ctrllimited="true" ctrlrange="-200 200"/>

    <motor name="Larm_shoulder_p_joint"  joint="Larm_shoulder_p_joint"  gear="1" ctrllimited="true" ctrlrange="-200 200"/>
    <motor name="Rarm_shoulder_p_joint"  joint="Rarm_shoulder_p_joint"  gear="1" ctrllimited="true" ctrlrange="-200 200"/>
  </actuator>

  <sensor>
    <accelerometer name="imu_acc" site="imu_site" />
    <gyro name="imu_gyro" site="imu_site" />
    <framepos name="imu_pos" objtype="site" objname="imu_site" />
    <framelinvel name="imu_linvel" objtype="site" objname="imu_site" />

    <framequat     name='orientation' objtype='site' noise='0.001' objname='imu'/>
    <framepos     name='position' objtype='site' noise='0.001' objname='imu'/>
    <gyro          name='angular-velocity'    site='imu' noise='0.005' cutoff='34.9'/>
    <velocimeter   name='linear-velocity'     site='imu' noise='0.001' cutoff='30'/>
    <accelerometer name='linear-acceleration' site='imu' noise='0.005' cutoff='157'/>
    <magnetometer  name='magnetometer'        site='imu'/>
  </sensor>
</mujoco>

