<mujoco model="bhr8_fc2">
  <compiler angle="radian" meshdir="../meshes/"/>
  <statistic meansize="0.201559" extent="2.948112" center="0.00499457 0 0.337764"/>

  <default>
      <joint limited='true'/>
      <motor ctrllimited='true'/>
      <geom  condim='4' contype="1" conaffinity="15" solref='0.001 2' friction='0.9 0.2 0.2'/>
      <equality solref='0.001 2'/>
      <default class='visualgeom'>
          <geom material='visualgeom' condim='1' contype='0' conaffinity='0'/>
      </default>
      <default class='visualgeom2'>
          <geom material='visualgeom2' condim='1' contype='0' conaffinity='0'/>
      </default>
      <default class='obstacle'>
          <geom material='obstacle' condim='3' contype='1' conaffinity='15'/>
      </default>
      <default class='leg_joint_param'>
          <!--<joint damping="0.01" frictionloss="0.01" armature="0.01"/>-->
          <joint damping="0.0" frictionloss="0.0" armature="0.0"/>
      </default>
  </default>

  <asset>
    <mesh name="torso" file="torso.stl"/>
    <mesh name="rhip1" file="rhip1.stl"/>
    <mesh name="rhip2" file="rhip2.stl"/>
    <mesh name="rthigh" file="rthigh.stl"/>
    <mesh name="rcalf" file="rcalf.stl"/>
    <mesh name="rankle" file="rankle.stl"/>
    <mesh name="rfoot" file="rfoot.stl"/>
    <mesh name="lhip1" file="lhip1.stl"/>
    <mesh name="lhip2" file="lhip2.stl"/>
    <mesh name="lthigh" file="lthigh.stl"/>
    <mesh name="lcalf" file="lcalf.stl"/>
    <mesh name="lankle" file="lankle.stl"/>
    <mesh name="lfoot" file="lfoot.stl"/>
    <mesh name="rshoulder1" file="rshoulder1.stl"/>
    <mesh name="rshoulder2" file="rshoulder2.stl"/>
    <mesh name="rbigarm" file="rbigarm.stl"/>
    <mesh name="rforearm" file="rforearm.stl"/>
    <mesh name="lshoulder1" file="lshoulder1.stl"/>
    <mesh name="lshoulder2" file="lshoulder2.stl"/>
    <mesh name="lbigarm" file="lbigarm.stl"/>
    <mesh name="lforearm" file="lforearm.stl"/>
  </asset>

  <asset>
    <!-- Set ground -->
    <texture name="grid" type="2d" builtin="checker" width="512" height="512" rgb1=".1 .2 .3" rgb2=".2 .3 .4"/>
    <material name="grid" texture="grid" texrepeat="1 1" texuniform="true" reflectance=".2"/>
  </asset>

  <option timestep="0.001" integrator="RK4">
    <flag frictionloss="enable" />
  </option>

  <visual>
    <map stiffness="300" force="0.1" zfar="30"/>
    <rgba haze="0.15 0.25 0.35 1"/>
    <global offwidth="2560" offheight="1440" elevation="-30" azimuth="120"/>
  </visual>

  <worldbody>
    <!-- Main Light Source -->
    <light name="main_light" diffuse="2 2 2" specular="0.5 0.5 0.5" pos="0 0 40" dir="0 0 -1" castshadow="true"/>
    <!-- Auxiliary Light Sources-->
    <light name="aux_light1" diffuse=".8 .8 .8" pos=" 10 0 1" dir="-1 0 0" castshadow="false"/>
    <light name="aux_light2" diffuse=".8 .8 .8" pos="-10 0 1" dir=" 1 0 0" castshadow="false"/>
    <light name="aux_light3" diffuse=".8 .8 .8" pos="0  10 1" dir="0 -1 0" castshadow="false"/>
    <light name="aux_light4" diffuse=".8 .8 .8" pos="0 -10 1" dir="0  1 0" castshadow="false"/>
    <geom name="floor" type="plane" size="0 0 0.05" material="grid"/>

    <!-- base -->
    <body name="torso" pos="0 0 0.92" euler="0 0 0">
      <inertial pos="-0.012982 0.001904 0.240391"  mass="24.091719" fullinertia="0.717329 0.608806 0.242843 0.001910 -0.031575 0.004632"/>
      <freejoint name="torso"/>

      <geom type="mesh" contype="0" conaffinity="0" group="1" density="0" rgba="0.752941 0.752941 0.752941 1" mesh="torso"/>
      <geom size="0.15 0.14 0.28" pos="0 0 0.25" type="box" rgba="0.752941 0.752941 0.752941 0"/>
      <site name="imu" pos="0 0 0" size="0.02" rgba="1 0 0 1" type="sphere" />

      <!-- r1 -->
      <body name="rhip1" pos="0 -0.1 0.02324">
        <inertial pos="-0.078509 0 -0.118031" quat="0.312936 0.634303 0.633788 0.313119" mass="2.58958" diaginertia="0.011987 0.0111943 0.00318774"/>
        <joint name="rhipYaw" pos="0 0 0" axis="0 0 1" range="-3.14 3.14" actuatorfrcrange="-100 100"/>
        <geom type="mesh" contype="0" conaffinity="0" group="1" density="0" rgba="0.752941 0.752941 0.752941 1" mesh="rhip1"/>
        <geom size="0.05 0.03" pos="-0.11 0 -0.14" quat="0.707388 0 0.706825 0" type="cylinder" rgba="0.752941 0.752941 0.752941 0"/>

        <!-- r2 -->
        <body name="rhip2" pos="-0.054 0 -0.13924">
          <inertial pos="0.051206 -0.00273 -0.000288" quat="-0.0508471 0.718896 0.0506336 0.691404" mass="2.70709" diaginertia="0.0040419 0.00361648 0.00344663"/>
          <joint name="rhipRoll" pos="0 0 0" axis="1 0 0" range="-3.14 3.14" actuatorfrcrange="-100 100"/>
          <geom type="mesh" contype="0" conaffinity="0" group="1" density="0" rgba="0.752941 0.752941 0.752941 1" mesh="rhip2"/>
          <geom size="0.05 0.04" pos="0.05 0 0" quat="0.707388 0.706825 0 0" type="cylinder" rgba="0.752941 0.752941 0.752941 0"/>

          <!-- r3 -->
          <body name="rthigh" pos="0.055 -0.0001 0">
            <inertial pos="0.005701 -0.002335 -0.170006" quat="0.999478 -0.00792791 -0.00348956 0.0311153" mass="3.59646" diaginertia="0.0430693 0.0409464 0.00582637"/>
            <joint name="rhipPitch" pos="0 0 0" axis="0 1 0" range="-3.14 3.14" actuatorfrcrange="-100 100"/>
            <geom type="mesh" contype="0" conaffinity="0" group="1" density="0" rgba="0.752941 0.752941 0.752941 1" mesh="rthigh"/>
            <geom size="0.05 0.05 0.16" pos="0 0 -0.23" type="box" rgba="0.752941 0.752941 0.752941 0"/>

            <!-- r4 -->
            <body name="rcalf" pos="0 0 -0.375">
              <inertial pos="0.003761 0 -0.143175" quat="0.99988 -0.000702889 -0.0153326 0.00193635" mass="2.51427" diaginertia="0.0176306 0.017018 0.00210037"/>
              <joint name="rknee" pos="0 0 0" axis="0 1 0" range="-3.14 3.14" actuatorfrcrange="-100 100"/>
              <geom type="mesh" contype="0" conaffinity="0" group="1" density="0" rgba="0.752941 0.752941 0.752941 1" mesh="rcalf"/>
              <geom size="0.04 0.04 0.1" pos="0 0 -0.18" type="box" rgba="0.752941 0.752941 0.752941 0"/>

              <!-- r5 -->
              <body name="rankle" pos="0 0 -0.35">
                <inertial pos="-0.025377 0.000124 0.003585" quat="0.513827 0.48578 0.48578 0.513827" mass="0.139581" diaginertia="0.000117 0.000111225 3.97754e-05"/>
                <joint name="rankle1" pos="0 0 0" axis="0 1 0" range="-3.14 3.14" actuatorfrcrange="-100 100"/>
                <geom type="mesh" contype="0" conaffinity="0" group="1" density="0" rgba="0.752941 0.752941 0.752941 1" mesh="rankle"/>

                <!-- r6 -->
                <body name="rfoot" pos="0.031 0 0">
                  <inertial pos="-0.016884 0.000166 -0.054343" quat="-0.00139322 0.658253 -0.0050555 0.752779" mass="1.50445" diaginertia="0.00652476 0.00619614 0.0011981"/>
                  <joint name="rankle2" pos="0 0 0" axis="1 0 0" range="-3.14 3.14" actuatorfrcrange="-100 100"/>
                  <geom type="mesh" contype="0" conaffinity="0" group="1" density="0" rgba="0.752941 0.752941 0.752941 1" mesh="rfoot"/>
                  <geom type="mesh" rgba="0.752941 0.752941 0.752941 0" mesh="rfoot"/>
                </body>
              </body>
            </body>
          </body>
        </body>
      </body>

        <!-- l1 -->
      <body name="lhip1" pos="0 0.1 0.02324">
        <inertial pos="-0.078509 0 -0.118031" quat="0.312936 0.634303 0.633788 0.313119" mass="2.58958" diaginertia="0.011987 0.0111943 0.00318774"/>
        <joint name="lhipYaw" pos="0 0 0" axis="0 0 1" range="-3.14 3.14" actuatorfrcrange="-100 100"/>
        <geom type="mesh" contype="0" conaffinity="0" group="1" density="0" rgba="0.752941 0.752941 0.752941 1" mesh="lhip1"/>
        <geom size="0.05 0.03" pos="-0.11 0 -0.14" quat="0.707388 0 0.706825 0" type="cylinder" rgba="0.752941 0.752941 0.752941 0"/>

        <!-- l2 -->
        <body name="lhip2" pos="-0.054 0 -0.13924">
          <inertial pos="0.051206 0.002733 -0.00028" quat="0.0501181 0.718914 -0.051553 0.691371" mass="2.70722" diaginertia="0.00404191 0.00361648 0.00344661"/>
          <joint name="lhipRoll" pos="0 0 0" axis="1 0 0" range="-3.14 3.14" actuatorfrcrange="-100 100"/>
          <geom type="mesh" contype="0" conaffinity="0" group="1" density="0" rgba="0.752941 0.752941 0.752941 1" mesh="lhip2"/>
          <geom size="0.05 0.04" pos="0.05 0 0" quat="0.707388 0.706825 0 0" type="cylinder" rgba="0.752941 0.752941 0.752941 0"/>

          <!-- l3 -->
          <body name="lthigh" pos="0.055 0 0">
            <inertial pos="0.004804 0.002343 -0.169952" quat="0.99957 0.00788906 -0.00488581 -0.0278185" mass="3.59646" diaginertia="0.0430607 0.0408405 0.00572671"/>
            <joint name="lhipPitch" pos="0 0 0" axis="0 1 0" range="-3.14 3.14" actuatorfrcrange="-100 100"/>
            <geom type="mesh" contype="0" conaffinity="0" group="1" density="0" rgba="0.752941 0.752941 0.752941 1" mesh="lthigh"/>
            <geom size="0.05 0.05 0.16" pos="0 0 -0.23" type="box" rgba="0.752941 0.752941 0.752941 0"/>

            <!-- l4 -->
            <body name="lcalf" pos="0 0 -0.375">
              <inertial pos="0.003757 -0.00029 -0.143175" quat="0.999882 0.000728441 -0.0153344 0.000562778" mass="2.51427" diaginertia="0.0176306 0.017019 0.00210036"/>
              <joint name="lknee" pos="0 0 0" axis="0 1 0" range="-3.14 3.14" actuatorfrcrange="-100 100"/>
              <geom type="mesh" contype="0" conaffinity="0" group="1" density="0" rgba="0.752941 0.752941 0.752941 1" mesh="lcalf"/>
              <geom size="0.04 0.04 0.1" pos="0 0 -0.18" type="box" rgba="0.752941 0.752941 0.752941 0"/>

              <!-- l5 -->
              <body name="lankle" pos="0 0 -0.35">
                <inertial pos="-0.025377 0.000124 0.003585" quat="0.513827 0.48578 0.48578 0.513827" mass="0.139581" diaginertia="0.000117 0.000111225 3.97754e-05"/>
                <joint name="lankle1" pos="0 0 0" axis="0 1 0" range="-3.14 3.14" actuatorfrcrange="-100 100"/>
                <geom type="mesh" contype="0" conaffinity="0" group="1" density="0" rgba="0.752941 0.752941 0.752941 1" mesh="lankle"/>

                <!-- l6 -->
                <body name="lfoot" pos="0.031 0 0">
                  <inertial pos="-0.016876 -0.000173 -0.054342" quat="0.0024359 0.658246 0.00581857 0.752776" mass="1.50435" diaginertia="0.00652477 0.00619511 0.00119811"/>
                  <joint name="lankle2" pos="0 0 0" axis="1 0 0" range="-3.14 3.14" actuatorfrcrange="-100 100"/>
                  <geom type="mesh" contype="0" conaffinity="0" group="1" density="0" rgba="0.752941 0.752941 0.752941 1" mesh="lfoot"/>
                  <geom type="mesh" rgba="0.752941 0.752941 0.752941 0" mesh="lfoot"/>
                </body>
              </body>
            </body>
          </body>
        </body>
      </body>

        <!-- rarm1 -->
      <body name="rshoulder1" pos="-0.02625 -0.13476 0.389">
        <inertial pos="-0.072957 -0.077869 0" quat="0.0679918 0.703732 -0.0683079 0.703898" mass="1.93819" diaginertia="0.007542 0.00713155 0.00236245"/>
        <joint name="rshoulderPitch" pos="0 0 0" axis="0 -1 0" range="-3.14 3.14" actuatorfrcrange="-100 100"/>
        <geom type="mesh" contype="0" conaffinity="0" group="1" density="0" rgba="0.752941 0.752941 0.752941 1" mesh="rshoulder1"/>

        <!-- rarm2 -->
        <body name="rshoulder2" pos="-0.049 -0.08424 0">
          <inertial pos="0.051 0 -0.017501" quat="0.45725 0.539372 0.539372 0.45725" mass="2.11646" diaginertia="0.003457 0.00313511 0.00264589"/>
          <joint name="rshoulderRoll" pos="0 0 0" axis="1 0 0" range="-3.14 3.14" actuatorfrcrange="-100 100"/>
          <geom type="mesh" contype="0" conaffinity="0" group="1" density="0" rgba="0.752941 0.752941 0.752941 1" mesh="rshoulder2"/>

          <!-- rarm3 -->
          <body name="rbigarm" pos="0.049 0 -0.05">
            <inertial pos="0.002752 0 -0.123717" quat="0.999552 0 0.0299255 0" mass="2.50306" diaginertia="0.0121441 0.011971 0.00122592"/>
            <joint name="rshoulderYaw" pos="0 0 0" axis="0 0 1" range="-3.14 3.14" actuatorfrcrange="-100 100"/>
            <geom type="mesh" contype="0" conaffinity="0" group="1" density="0" rgba="0.752941 0.752941 0.752941 1" mesh="rbigarm"/>

            <!-- rarm4 -->
            <body name="rforearm" pos="0 -0.01 -0.30324" quat="0.696707 0 -0.717356 0">
              <inertial pos="0.002409 0.01 -0.09" quat="0.707065 -0.00771561 -0.00771561 0.707065" mass="0.381283" diaginertia="0.001374 0.00136863 3.9367e-05"/>
              <joint name="relbow" pos="0 0 0" axis="0 -1 0" range="-3.14 3.14" actuatorfrcrange="-100 100"/>
              <geom type="mesh" contype="0" conaffinity="0" group="1" density="0" rgba="0.752941 0.752941 0.752941 1" mesh="rforearm"/>
            </body>
          </body>
        </body>
      </body>

        <!-- larm1 -->
      <body name="lshoulder1" pos="-0.02625 0.13476 0.389">
        <inertial pos="-0.072957 0.077869 0" quat="-0.0683079 0.703898 0.0679918 0.703732" mass="1.93819" diaginertia="0.007542 0.00713155 0.00236245"/>
        <joint name="lshoulderPitch" pos="0 0 0" axis="0 1 0" range="-3.14 3.14" actuatorfrcrange="-100 100"/>
        <geom type="mesh" contype="0" conaffinity="0" group="1" density="0" rgba="0.752941 0.752941 0.752941 1" mesh="lshoulder1"/>

        <!-- larm2 -->
        <body name="lshoulder2" pos="-0.049 0.08424 0">
          <inertial pos="0.051 0 -0.017501" quat="0.45725 0.539372 0.539372 0.45725" mass="2.11646" diaginertia="0.003457 0.00313511 0.00264589"/>
          <joint name="lshoulderRoll" pos="0 0 0" axis="1 0 0" range="-3.14 3.14" actuatorfrcrange="-100 100"/>
          <geom type="mesh" contype="0" conaffinity="0" group="1" density="0" rgba="0.752941 0.752941 0.752941 1" mesh="lshoulder2"/>

          <!-- larm3 -->
          <body name="lbigarm" pos="0.049 0 -0.05">
            <inertial pos="0.002752 0 -0.123717" quat="0.999552 0 0.0299255 0" mass="2.50306" diaginertia="0.0121441 0.011971 0.00122592"/>
            <joint name="lshoulderYaw" pos="0 0 0" axis="0 0 1" range="-3.14 3.14" actuatorfrcrange="-100 100"/>
            <geom type="mesh" contype="0" conaffinity="0" group="1" density="0" rgba="0.752941 0.752941 0.752941 1" mesh="lbigarm"/>

            <!-- larm4 -->
            <body name="lforearm" pos="0 0.01 -0.30324" quat="0.696707 0 -0.717356 0">
              <inertial pos="0.0024 -0.01 -0.09" quat="0.707065 -0.00771561 -0.00771561 0.707065" mass="0.381283" diaginertia="0.001374 0.00136863 3.9367e-05"/>
              <joint name="lelbow" pos="0 0 0" axis="0 1 0" range="-3.14 3.14" actuatorfrcrange="-100 100"/>
              <geom type="mesh" contype="0" conaffinity="0" group="1" density="0" rgba="0.752941 0.752941 0.752941 1" mesh="lforearm"/>
            </body>
          </body>
        </body>
      </body>
    </body>
  </worldbody>

  <actuator>
    <motor name="rhipYaw"   joint="rhipYaw"   gear="1" ctrllimited="true" ctrlrange="-200 200"/>
    <motor name="rhipRoll"  joint="rhipRoll"  gear="1" ctrllimited="true" ctrlrange="-200 200"/>
    <motor name="rhipPitch"  joint="rhipPitch"  gear="1" ctrllimited="true" ctrlrange="-200 200"/>
    <motor name="rknee"  joint="rknee"  gear="1" ctrllimited="true" ctrlrange="-200 200"/>
    <motor name="rankle1"   joint="rankle1"   gear="1" ctrllimited="true" ctrlrange="-200 200"/>
    <motor name="rankle2"  joint="rankle2"  gear="1" ctrllimited="true" ctrlrange="-200 200"/>

    <motor name="lhipYaw"  joint="lhipYaw"  gear="1" ctrllimited="true" ctrlrange="-200 200"/>
    <motor name="lhipRoll"  joint="lhipRoll"  gear="1" ctrllimited="true" ctrlrange="-200 200"/>
    <motor name="lhipPitch"  joint="lhipPitch"  gear="1" ctrllimited="true" ctrlrange="-200 200"/>
    <motor name="lknee"  joint="lknee"  gear="1" ctrllimited="true" ctrlrange="-200 200"/>
    <motor name="lankle1"   joint="lankle1"   gear="1" ctrllimited="true" ctrlrange="-200 200"/>
    <motor name="lankle2"  joint="lankle2"  gear="1" ctrllimited="true" ctrlrange="-200 200"/>

    <motor name="rshoulderPitch"  joint="rshoulderPitch"  gear="1" ctrllimited="true" ctrlrange="-200 200"/>
    <motor name="rshoulderRoll"  joint="rshoulderRoll"  gear="1" ctrllimited="true" ctrlrange="-200 200"/>
    <motor name="rshoulderYaw"  joint="rshoulderYaw"  gear="1" ctrllimited="true" ctrlrange="-200 200"/>
    <motor name="relbow"  joint="relbow"  gear="1" ctrllimited="true" ctrlrange="-200 200"/>

    <motor name="lshoulderPitch"  joint="lshoulderPitch"  gear="1" ctrllimited="true" ctrlrange="-200 200"/>
    <motor name="lshoulderRoll"  joint="lshoulderRoll"  gear="1" ctrllimited="true" ctrlrange="-200 200"/>
    <motor name="lshoulderYaw"  joint="lshoulderYaw"  gear="1" ctrllimited="true" ctrlrange="-200 200"/>
    <motor name="lelbow"  joint="lelbow"  gear="1" ctrllimited="true" ctrlrange="-200 200"/>
  </actuator>

  <sensor>
    <framequat     name='orientation' objtype='site' noise='0.001' objname='imu'/>
    <framepos     name='position' objtype='site' noise='0.001' objname='imu'/>
    <gyro          name='angular-velocity'    site='imu' noise='0.005' cutoff='34.9'/>
    <velocimeter   name='linear-velocity'     site='imu' noise='0.001' cutoff='30'/>
    <accelerometer name='linear-acceleration' site='imu' noise='0.005' cutoff='157'/>
    <magnetometer  name='magnetometer'        site='imu'/>
  </sensor>
</mujoco>

